Workbook
Name CURRENTV: Legenda!$B$1
Name LASTV: Legenda!$B$2

Sheet Agenda2526
A1: 2526 | B1: CV | C1: =CURRENTV -> 46089 | N1: MOD_1 | O1: MOD_2 | P1: MOD_3 | Q1: MOD_4 | R1: MOD_5 | S1: MOD_6 | T1: MOD_7 | U1: MOD_8
D2: G1 | E2: G2 | F2: G3 | G2: G4 | H2: G5 | I2: G6 | J2: Personeel | K2: Algemeen | L2: VIEW | N2: MOD_1 | O2: MOD_2 | P2: MOD_3 | Q2: MOD_4 | R2: MOD_5 | S2: MOD_6 | T2: MOD_7 | U2: MOD_8
A3: 36 | B3: ma | C3: 45901 | D3: =CONCATENATE(CALC2223!A2," ",CALC2223!C2," ",CALC2223!E2) | E3: =CONCATENATE(CALC2223!G2," ",CALC2223!I2," ",CALC2223!K2) | F3: =CONCATENATE(CALC2223!M2," ",CALC2223!O2," ",CALC2223!Q2) | G3: =CONCATENATE(CALC2223!S2," ",CALC2223!U2," ",CALC2223!W2) | H3: =CONCATENATE(CALC2223!Y2," ",CALC2223!AA2," ",CALC2223!AC2) | I3: =CONCATENATE(CALC2223!AE2," ",CALC2223!AG2," ",CALC2223!AI2) | J3: =CONCATENATE(CALC2223!AK2," ",CALC2223!AM2," ",CALC2223!AO2) | K3: =CONCATENATE(CALC2223!AQ2," ",CALC2223!AS2," ",CALC2223!AU2," ",CALC2223!AW2) -> personeelsdag | L3: =IF(C3<TODAY(),"verleden","actueel") -> verleden | N3: =OR(VALUE(CALC2223!B2)>VALUE(LASTV),VALUE(CALC2223!D2)>VALUE(LASTV),VALUE(CALC2223!F2)>VALUE(LASTV)) -> FALSE | O3: =OR(VALUE(CALC2223!H2)>VALUE(LASTV),VALUE(CALC2223!J2)>VALUE(LASTV),VALUE(CALC2223!L2)>VALUE(LASTV)) -> FALSE | P3: =OR(VALUE(CALC2223!N2)>VALUE(LASTV),VALUE(CALC2223!P2)>VALUE(LASTV),VALUE(CALC2223!R2)>VALUE(LASTV)) -> FALSE | Q3: =OR(VALUE(CALC2223!T2)>VALUE(LASTV),VALUE(CALC2223!V2)>VALUE(LASTV),VALUE(CALC2223!X2)>VALUE(LASTV)) -> FALSE | R3: =OR(VALUE(CALC2223!Z2)>VALUE(LASTV),VALUE(CALC2223!AB2)>VALUE(LASTV),VALUE(CALC2223!AD2)>VALUE(LASTV)) -> FALSE | S3: =OR(VALUE(CALC2223!AF2)>VALUE(LASTV),VALUE(CALC2223!AH2)>VALUE(LASTV),VALUE(CALC2223!AJ2)>VALUE(LASTV)) -> FALSE | T3: =OR(VALUE(CALC2223!AL2)>VALUE(LASTV),VALUE(CALC2223!AN2)>VALUE(LASTV),VALUE(CALC2223!AP2)>VALUE(LASTV)) -> FALSE | U3: =OR(VALUE(CALC2223!AR2)>VALUE(LASTV),VALUE(CALC2223!AT2)>VALUE(LASTV),VALUE(CALC2223!AV2)>VALUE(LASTV)) -> FALSE
B4: di | C4: 45902 | D4: =CONCATENATE(CALC2223!A3," ",CALC2223!C3," ",CALC2223!E3) | E4: =CONCATENATE(CALC2223!G3," ",CALC2223!I3," ",CALC2223!K3) | F4: =CONCATENATE(CALC2223!M3," ",CALC2223!O3," ",CALC2223!Q3) | G4: =CONCATENATE(CALC2223!S3," ",CALC2223!U3," ",CALC2223!W3) | H4: =CONCATENATE(CALC2223!Y3," ",CALC2223!AA3," ",CALC2223!AC3) | I4: =CONCATENATE(CALC2223!AE3," ",CALC2223!AG3," ",CALC2223!AI3) | J4: =CONCATENATE(CALC2223!AK3," ",CALC2223!AM3," ",CALC2223!AO3) | K4: =CONCATENATE(CALC2223!AQ3," ",CALC2223!AS3," ",CALC2223!AU3," ",CALC2223!AW3) -> CGUweek1; fotograaf | L4: =IF(C4<TODAY(),"verleden","actueel") -> verleden | N4: =OR(VALUE(CALC2223!B3)>VALUE(LASTV),VALUE(CALC2223!D3)>VALUE(LASTV),VALUE(CALC2223!F3)>VALUE(LASTV)) -> FALSE | O4: =OR(VALUE(CALC2223!H3)>VALUE(LASTV),VALUE(CALC2223!J3)>VALUE(LASTV),VALUE(CALC2223!L3)>VALUE(LASTV)) -> FALSE | P4: =OR(VALUE(CALC2223!N3)>VALUE(LASTV),VALUE(CALC2223!P3)>VALUE(LASTV),VALUE(CALC2223!R3)>VALUE(LASTV)) -> FALSE | Q4: =OR(VALUE(CALC2223!T3)>VALUE(LASTV),VALUE(CALC2223!V3)>VALUE(LASTV),VALUE(CALC2223!X3)>VALUE(LASTV)) -> FALSE | R4: =OR(VALUE(CALC2223!Z3)>VALUE(LASTV),VALUE(CALC2223!AB3)>VALUE(LASTV),VALUE(CALC2223!AD3)>VALUE(LASTV)) -> FALSE | S4: =OR(VALUE(CALC2223!AF3)>VALUE(LASTV),VALUE(CALC2223!AH3)>VALUE(LASTV),VALUE(CALC2223!AJ3)>VALUE(LASTV)) -> FALSE | T4: =OR(VALUE(CALC2223!AL3)>VALUE(LASTV),VALUE(CALC2223!AN3)>VALUE(LASTV),VALUE(CALC2223!AP3)>VALUE(LASTV)) -> FALSE | U4: =OR(VALUE(CALC2223!AR3)>VALUE(LASTV),VALUE(CALC2223!AT3)>VALUE(LASTV),VALUE(CALC2223!AV3)>VALUE(LASTV)) -> FALSE
B5: wo | C5: 45903 | D5: =CONCATENATE(CALC2223!A4," ",CALC2223!C4," ",CALC2223!E4) | E5: =CONCATENATE(CALC2223!G4," ",CALC2223!I4," ",CALC2223!K4) | F5: =CONCATENATE(CALC2223!M4," ",CALC2223!O4," ",CALC2223!Q4) | G5: =CONCATENATE(CALC2223!S4," ",CALC2223!U4," ",CALC2223!W4) | H5: =CONCATENATE(CALC2223!Y4," ",CALC2223!AA4," ",CALC2223!AC4) | I5: =CONCATENATE(CALC2223!AE4," ",CALC2223!AG4," ",CALC2223!AI4) | J5: =CONCATENATE(CALC2223!AK4," ",CALC2223!AM4," ",CALC2223!AO4) | K5: =CONCATENATE(CALC2223!AQ4," ",CALC2223!AS4," ",CALC2223!AU4," ",CALC2223!AW4) | L5: =IF(C5<TODAY(),"verleden","actueel") -> verleden | N5: =OR(VALUE(CALC2223!B4)>VALUE(LASTV),VALUE(CALC2223!D4)>VALUE(LASTV),VALUE(CALC2223!F4)>VALUE(LASTV)) -> FALSE | O5: =OR(VALUE(CALC2223!H4)>VALUE(LASTV),VALUE(CALC2223!J4)>VALUE(LASTV),VALUE(CALC2223!L4)>VALUE(LASTV)) -> FALSE | P5: =OR(VALUE(CALC2223!N4)>VALUE(LASTV),VALUE(CALC2223!P4)>VALUE(LASTV),VALUE(CALC2223!R4)>VALUE(LASTV)) -> FALSE | Q5: =OR(VALUE(CALC2223!T4)>VALUE(LASTV),VALUE(CALC2223!V4)>VALUE(LASTV),VALUE(CALC2223!X4)>VALUE(LASTV)) -> FALSE | R5: =OR(VALUE(CALC2223!Z4)>VALUE(LASTV),VALUE(CALC2223!AB4)>VALUE(LASTV),VALUE(CALC2223!AD4)>VALUE(LASTV)) -> FALSE | S5: =OR(VALUE(CALC2223!AF4)>VALUE(LASTV),VALUE(CALC2223!AH4)>VALUE(LASTV),VALUE(CALC2223!AJ4)>VALUE(LASTV)) -> FALSE | T5: =OR(VALUE(CALC2223!AL4)>VALUE(LASTV),VALUE(CALC2223!AN4)>VALUE(LASTV),VALUE(CALC2223!AP4)>VALUE(LASTV)) -> FALSE | U5: =OR(VALUE(CALC2223!AR4)>VALUE(LASTV),VALUE(CALC2223!AT4)>VALUE(LASTV),VALUE(CALC2223!AV4)>VALUE(LASTV)) -> FALSE
B6: do | C6: 45904 | D6: =CONCATENATE(CALC2223!A5," ",CALC2223!C5," ",CALC2223!E5) | E6: =CONCATENATE(CALC2223!G5," ",CALC2223!I5," ",CALC2223!K5) | F6: =CONCATENATE(CALC2223!M5," ",CALC2223!O5," ",CALC2223!Q5) | G6: =CONCATENATE(CALC2223!S5," ",CALC2223!U5," ",CALC2223!W5) | H6: =CONCATENATE(CALC2223!Y5," ",CALC2223!AA5," ",CALC2223!AC5) | I6: =CONCATENATE(CALC2223!AE5," ",CALC2223!AG5," ",CALC2223!AI5) | J6: =CONCATENATE(CALC2223!AK5," ",CALC2223!AM5," ",CALC2223!AO5) -> secties#1 | K6: =CONCATENATE(CALC2223!AQ5," ",CALC2223!AS5," ",CALC2223!AU5," ",CALC2223!AW5) -> ouderavond brugklas | L6: =IF(C6<TODAY(),"verleden","actueel") -> verleden | N6: =OR(VALUE(CALC2223!B5)>VALUE(LASTV),VALUE(CALC2223!D5)>VALUE(LASTV),VALUE(CALC2223!F5)>VALUE(LASTV)) -> FALSE | O6: =OR(VALUE(CALC2223!H5)>VALUE(LASTV),VALUE(CALC2223!J5)>VALUE(LASTV),VALUE(CALC2223!L5)>VALUE(LASTV)) -> FALSE | P6: =OR(VALUE(CALC2223!N5)>VALUE(LASTV),VALUE(CALC2223!P5)>VALUE(LASTV),VALUE(CALC2223!R5)>VALUE(LASTV)) -> FALSE | Q6: =OR(VALUE(CALC2223!T5)>VALUE(LASTV),VALUE(CALC2223!V5)>VALUE(LASTV),VALUE(CALC2223!X5)>VALUE(LASTV)) -> FALSE | R6: =OR(VALUE(CALC2223!Z5)>VALUE(LASTV),VALUE(CALC2223!AB5)>VALUE(LASTV),VALUE(CALC2223!AD5)>VALUE(LASTV)) -> FALSE | S6: =OR(VALUE(CALC2223!AF5)>VALUE(LASTV),VALUE(CALC2223!AH5)>VALUE(LASTV),VALUE(CALC2223!AJ5)>VALUE(LASTV)) -> FALSE | T6: =OR(VALUE(CALC2223!AL5)>VALUE(LASTV),VALUE(CALC2223!AN5)>VALUE(LASTV),VALUE(CALC2223!AP5)>VALUE(LASTV)) -> FALSE | U6: =OR(VALUE(CALC2223!AR5)>VALUE(LASTV),VALUE(CALC2223!AT5)>VALUE(LASTV),VALUE(CALC2223!AV5)>VALUE(LASTV)) -> FALSE
B7: vr | C7: 45905 | D7: =CONCATENATE(CALC2223!A6," ",CALC2223!C6," ",CALC2223!E6) | E7: =CONCATENATE(CALC2223!G6," ",CALC2223!I6," ",CALC2223!K6) | F7: =CONCATENATE(CALC2223!M6," ",CALC2223!O6," ",CALC2223!Q6) | G7: =CONCATENATE(CALC2223!S6," ",CALC2223!U6," ",CALC2223!W6) | H7: =CONCATENATE(CALC2223!Y6," ",CALC2223!AA6," ",CALC2223!AC6) | I7: =CONCATENATE(CALC2223!AE6," ",CALC2223!AG6," ",CALC2223!AI6) -> opgave herkansingen 17 uur | J7: =CONCATENATE(CALC2223!AK6," ",CALC2223!AM6," ",CALC2223!AO6) | K7: =CONCATENATE(CALC2223!AQ6," ",CALC2223!AS6," ",CALC2223!AU6," ",CALC2223!AW6) -> start lessen Lacadeia middag | L7: =IF(C7<TODAY(),"verleden","actueel") -> verleden | N7: =OR(VALUE(CALC2223!B6)>VALUE(LASTV),VALUE(CALC2223!D6)>VALUE(LASTV),VALUE(CALC2223!F6)>VALUE(LASTV)) -> FALSE | O7: =OR(VALUE(CALC2223!H6)>VALUE(LASTV),VALUE(CALC2223!J6)>VALUE(LASTV),VALUE(CALC2223!L6)>VALUE(LASTV)) -> FALSE | P7: =OR(VALUE(CALC2223!N6)>VALUE(LASTV),VALUE(CALC2223!P6)>VALUE(LASTV),VALUE(CALC2223!R6)>VALUE(LASTV)) -> FALSE | Q7: =OR(VALUE(CALC2223!T6)>VALUE(LASTV),VALUE(CALC2223!V6)>VALUE(LASTV),VALUE(CALC2223!X6)>VALUE(LASTV)) -> FALSE | R7: =OR(VALUE(CALC2223!Z6)>VALUE(LASTV),VALUE(CALC2223!AB6)>VALUE(LASTV),VALUE(CALC2223!AD6)>VALUE(LASTV)) -> FALSE | S7: =OR(VALUE(CALC2223!AF6)>VALUE(LASTV),VALUE(CALC2223!AH6)>VALUE(LASTV),VALUE(CALC2223!AJ6)>VALUE(LASTV)) -> FALSE | T7: =OR(VALUE(CALC2223!AL6)>VALUE(LASTV),VALUE(CALC2223!AN6)>VALUE(LASTV),VALUE(CALC2223!AP6)>VALUE(LASTV)) -> FALSE | U7: =OR(VALUE(CALC2223!AR6)>VALUE(LASTV),VALUE(CALC2223!AT6)>VALUE(LASTV),VALUE(CALC2223!AV6)>VALUE(LASTV)) -> FALSE
B8: za | C8: 45906 | D8: =CONCATENATE(CALC2223!A7," ",CALC2223!C7," ",CALC2223!E7) | E8: =CONCATENATE(CALC2223!G7," ",CALC2223!I7," ",CALC2223!K7) | F8: =CONCATENATE(CALC2223!M7," ",CALC2223!O7," ",CALC2223!Q7) | G8: =CONCATENATE(CALC2223!S7," ",CALC2223!U7," ",CALC2223!W7) | H8: =CONCATENATE(CALC2223!Y7," ",CALC2223!AA7," ",CALC2223!AC7) | I8: =CONCATENATE(CALC2223!AE7," ",CALC2223!AG7," ",CALC2223!AI7) | J8: =CONCATENATE(CALC2223!AK7," ",CALC2223!AM7," ",CALC2223!AO7) | K8: =CONCATENATE(CALC2223!AQ7," ",CALC2223!AS7," ",CALC2223!AU7," ",CALC2223!AW7) | L8: =IF(C8<TODAY(),"verleden","actueel") -> verleden | N8: =OR(VALUE(CALC2223!B7)>VALUE(LASTV),VALUE(CALC2223!D7)>VALUE(LASTV),VALUE(CALC2223!F7)>VALUE(LASTV)) -> FALSE | O8: =OR(VALUE(CALC2223!H7)>VALUE(LASTV),VALUE(CALC2223!J7)>VALUE(LASTV),VALUE(CALC2223!L7)>VALUE(LASTV)) -> FALSE | P8: =OR(VALUE(CALC2223!N7)>VALUE(LASTV),VALUE(CALC2223!P7)>VALUE(LASTV),VALUE(CALC2223!R7)>VALUE(LASTV)) -> FALSE | Q8: =OR(VALUE(CALC2223!T7)>VALUE(LASTV),VALUE(CALC2223!V7)>VALUE(LASTV),VALUE(CALC2223!X7)>VALUE(LASTV)) -> FALSE | R8: =OR(VALUE(CALC2223!Z7)>VALUE(LASTV),VALUE(CALC2223!AB7)>VALUE(LASTV),VALUE(CALC2223!AD7)>VALUE(LASTV)) -> FALSE | S8: =OR(VALUE(CALC2223!AF7)>VALUE(LASTV),VALUE(CALC2223!AH7)>VALUE(LASTV),VALUE(CALC2223!AJ7)>VALUE(LASTV)) -> FALSE | T8: =OR(VALUE(CALC2223!AL7)>VALUE(LASTV),VALUE(CALC2223!AN7)>VALUE(LASTV),VALUE(CALC2223!AP7)>VALUE(LASTV)) -> FALSE | U8: =OR(VALUE(CALC2223!AR7)>VALUE(LASTV),VALUE(CALC2223!AT7)>VALUE(LASTV),VALUE(CALC2223!AV7)>VALUE(LASTV)) -> FALSE
B9: zo | C9: 45907 | D9: =CONCATENATE(CALC2223!A8," ",CALC2223!C8," ",CALC2223!E8) | E9: =CONCATENATE(CALC2223!G8," ",CALC2223!I8," ",CALC2223!K8) | F9: =CONCATENATE(CALC2223!M8," ",CALC2223!O8," ",CALC2223!Q8) | G9: =CONCATENATE(CALC2223!S8," ",CALC2223!U8," ",CALC2223!W8) | H9: =CONCATENATE(CALC2223!Y8," ",CALC2223!AA8," ",CALC2223!AC8) | I9: =CONCATENATE(CALC2223!AE8," ",CALC2223!AG8," ",CALC2223!AI8) | J9: =CONCATENATE(CALC2223!AK8," ",CALC2223!AM8," ",CALC2223!AO8) | K9: =CONCATENATE(CALC2223!AQ8," ",CALC2223!AS8," ",CALC2223!AU8," ",CALC2223!AW8) | L9: =IF(C9<TODAY(),"verleden","actueel") -> verleden | N9: =OR(VALUE(CALC2223!B8)>VALUE(LASTV),VALUE(CALC2223!D8)>VALUE(LASTV),VALUE(CALC2223!F8)>VALUE(LASTV)) -> FALSE | O9: =OR(VALUE(CALC2223!H8)>VALUE(LASTV),VALUE(CALC2223!J8)>VALUE(LASTV),VALUE(CALC2223!L8)>VALUE(LASTV)) -> FALSE | P9: =OR(VALUE(CALC2223!N8)>VALUE(LASTV),VALUE(CALC2223!P8)>VALUE(LASTV),VALUE(CALC2223!R8)>VALUE(LASTV)) -> FALSE | Q9: =OR(VALUE(CALC2223!T8)>VALUE(LASTV),VALUE(CALC2223!V8)>VALUE(LASTV),VALUE(CALC2223!X8)>VALUE(LASTV)) -> FALSE | R9: =OR(VALUE(CALC2223!Z8)>VALUE(LASTV),VALUE(CALC2223!AB8)>VALUE(LASTV),VALUE(CALC2223!AD8)>VALUE(LASTV)) -> FALSE | S9: =OR(VALUE(CALC2223!AF8)>VALUE(LASTV),VALUE(CALC2223!AH8)>VALUE(LASTV),VALUE(CALC2223!AJ8)>VALUE(LASTV)) -> FALSE | T9: =OR(VALUE(CALC2223!AL8)>VALUE(LASTV),VALUE(CALC2223!AN8)>VALUE(LASTV),VALUE(CALC2223!AP8)>VALUE(LASTV)) -> FALSE | U9: =OR(VALUE(CALC2223!AR8)>VALUE(LASTV),VALUE(CALC2223!AT8)>VALUE(LASTV),VALUE(CALC2223!AV8)>VALUE(LASTV)) -> FALSE
A10: 37 | B10: ma | C10: 45908 | D10: =CONCATENATE(CALC2223!A9," ",CALC2223!C9," ",CALC2223!E9) | E10: =CONCATENATE(CALC2223!G9," ",CALC2223!I9," ",CALC2223!K9) | F10: =CONCATENATE(CALC2223!M9," ",CALC2223!O9," ",CALC2223!Q9) | G10: =CONCATENATE(CALC2223!S9," ",CALC2223!U9," ",CALC2223!W9) | H10: =CONCATENATE(CALC2223!Y9," ",CALC2223!AA9," ",CALC2223!AC9) | I10: =CONCATENATE(CALC2223!AE9," ",CALC2223!AG9," ",CALC2223!AI9) | J10: =CONCATENATE(CALC2223!AK9," ",CALC2223!AM9," ",CALC2223!AO9) | K10: =CONCATENATE(CALC2223!AQ9," ",CALC2223!AS9," ",CALC2223!AU9," ",CALC2223!AW9) | L10: =IF(C10<TODAY(),"verleden","actueel") -> verleden | N10: =OR(VALUE(CALC2223!B9)>VALUE(LASTV),VALUE(CALC2223!D9)>VALUE(LASTV),VALUE(CALC2223!F9)>VALUE(LASTV)) -> FALSE | O10: =OR(VALUE(CALC2223!H9)>VALUE(LASTV),VALUE(CALC2223!J9)>VALUE(LASTV),VALUE(CALC2223!L9)>VALUE(LASTV)) -> FALSE | P10: =OR(VALUE(CALC2223!N9)>VALUE(LASTV),VALUE(CALC2223!P9)>VALUE(LASTV),VALUE(CALC2223!R9)>VALUE(LASTV)) -> FALSE | Q10: =OR(VALUE(CALC2223!T9)>VALUE(LASTV),VALUE(CALC2223!V9)>VALUE(LASTV),VALUE(CALC2223!X9)>VALUE(LASTV)) -> FALSE | R10: =OR(VALUE(CALC2223!Z9)>VALUE(LASTV),VALUE(CALC2223!AB9)>VALUE(LASTV),VALUE(CALC2223!AD9)>VALUE(LASTV)) -> FALSE | S10: =OR(VALUE(CALC2223!AF9)>VALUE(LASTV),VALUE(CALC2223!AH9)>VALUE(LASTV),VALUE(CALC2223!AJ9)>VALUE(LASTV)) -> FALSE | T10: =OR(VALUE(CALC2223!AL9)>VALUE(LASTV),VALUE(CALC2223!AN9)>VALUE(LASTV),VALUE(CALC2223!AP9)>VALUE(LASTV)) -> FALSE | U10: =OR(VALUE(CALC2223!AR9)>VALUE(LASTV),VALUE(CALC2223!AT9)>VALUE(LASTV),VALUE(CALC2223!AV9)>VALUE(LASTV)) -> FALSE
B11: di | C11: 45909 | D11: =CONCATENATE(CALC2223!A10," ",CALC2223!C10," ",CALC2223!E10) | E11: =CONCATENATE(CALC2223!G10," ",CALC2223!I10," ",CALC2223!K10) | F11: =CONCATENATE(CALC2223!M10," ",CALC2223!O10," ",CALC2223!Q10) | G11: =CONCATENATE(CALC2223!S10," ",CALC2223!U10," ",CALC2223!W10) | H11: =CONCATENATE(CALC2223!Y10," ",CALC2223!AA10," ",CALC2223!AC10) | I11: =CONCATENATE(CALC2223!AE10," ",CALC2223!AG10," ",CALC2223!AI10) | J11: =CONCATENATE(CALC2223!AK10," ",CALC2223!AM10," ",CALC2223!AO10) | K11: =CONCATENATE(CALC2223!AQ10," ",CALC2223!AS10," ",CALC2223!AU10," ",CALC2223!AW10) | L11: =IF(C11<TODAY(),"verleden","actueel") -> verleden | N11: =OR(VALUE(CALC2223!B10)>VALUE(LASTV),VALUE(CALC2223!D10)>VALUE(LASTV),VALUE(CALC2223!F10)>VALUE(LASTV)) -> FALSE | O11: =OR(VALUE(CALC2223!H10)>VALUE(LASTV),VALUE(CALC2223!J10)>VALUE(LASTV),VALUE(CALC2223!L10)>VALUE(LASTV)) -> FALSE | P11: =OR(VALUE(CALC2223!N10)>VALUE(LASTV),VALUE(CALC2223!P10)>VALUE(LASTV),VALUE(CALC2223!R10)>VALUE(LASTV)) -> FALSE | Q11: =OR(VALUE(CALC2223!T10)>VALUE(LASTV),VALUE(CALC2223!V10)>VALUE(LASTV),VALUE(CALC2223!X10)>VALUE(LASTV)) -> FALSE | R11: =OR(VALUE(CALC2223!Z10)>VALUE(LASTV),VALUE(CALC2223!AB10)>VALUE(LASTV),VALUE(CALC2223!AD10)>VALUE(LASTV)) -> FALSE | S11: =OR(VALUE(CALC2223!AF10)>VALUE(LASTV),VALUE(CALC2223!AH10)>VALUE(LASTV),VALUE(CALC2223!AJ10)>VALUE(LASTV)) -> FALSE | T11: =OR(VALUE(CALC2223!AL10)>VALUE(LASTV),VALUE(CALC2223!AN10)>VALUE(LASTV),VALUE(CALC2223!AP10)>VALUE(LASTV)) -> FALSE | U11: =OR(VALUE(CALC2223!AR10)>VALUE(LASTV),VALUE(CALC2223!AT10)>VALUE(LASTV),VALUE(CALC2223!AV10)>VALUE(LASTV)) -> FALSE
B12: wo | C12: 45910 | D12: =CONCATENATE(CALC2223!A11," ",CALC2223!C11," ",CALC2223!E11) | E12: =CONCATENATE(CALC2223!G11," ",CALC2223!I11," ",CALC2223!K11) | F12: =CONCATENATE(CALC2223!M11," ",CALC2223!O11," ",CALC2223!Q11) | G12: =CONCATENATE(CALC2223!S11," ",CALC2223!U11," ",CALC2223!W11) | H12: =CONCATENATE(CALC2223!Y11," ",CALC2223!AA11," ",CALC2223!AC11) | I12: =CONCATENATE(CALC2223!AE11," ",CALC2223!AG11," ",CALC2223!AI11) | J12: =CONCATENATE(CALC2223!AK11," ",CALC2223!AM11," ",CALC2223!AO11) | K12: =CONCATENATE(CALC2223!AQ11," ",CALC2223!AS11," ",CALC2223!AU11," ",CALC2223!AW11) | L12: =IF(C12<TODAY(),"verleden","actueel") -> verleden | N12: =OR(VALUE(CALC2223!B11)>VALUE(LASTV),VALUE(CALC2223!D11)>VALUE(LASTV),VALUE(CALC2223!F11)>VALUE(LASTV)) -> FALSE | O12: =OR(VALUE(CALC2223!H11)>VALUE(LASTV),VALUE(CALC2223!J11)>VALUE(LASTV),VALUE(CALC2223!L11)>VALUE(LASTV)) -> FALSE | P12: =OR(VALUE(CALC2223!N11)>VALUE(LASTV),VALUE(CALC2223!P11)>VALUE(LASTV),VALUE(CALC2223!R11)>VALUE(LASTV)) -> FALSE | Q12: =OR(VALUE(CALC2223!T11)>VALUE(LASTV),VALUE(CALC2223!V11)>VALUE(LASTV),VALUE(CALC2223!X11)>VALUE(LASTV)) -> FALSE | R12: =OR(VALUE(CALC2223!Z11)>VALUE(LASTV),VALUE(CALC2223!AB11)>VALUE(LASTV),VALUE(CALC2223!AD11)>VALUE(LASTV)) -> FALSE | S12: =OR(VALUE(CALC2223!AF11)>VALUE(LASTV),VALUE(CALC2223!AH11)>VALUE(LASTV),VALUE(CALC2223!AJ11)>VALUE(LASTV)) -> FALSE | T12: =OR(VALUE(CALC2223!AL11)>VALUE(LASTV),VALUE(CALC2223!AN11)>VALUE(LASTV),VALUE(CALC2223!AP11)>VALUE(LASTV)) -> FALSE | U12: =OR(VALUE(CALC2223!AR11)>VALUE(LASTV),VALUE(CALC2223!AT11)>VALUE(LASTV),VALUE(CALC2223!AV11)>VALUE(LASTV)) -> FALSE
B13: do | C13: 45911 | D13: =CONCATENATE(CALC2223!A12," ",CALC2223!C12," ",CALC2223!E12) | E13: =CONCATENATE(CALC2223!G12," ",CALC2223!I12," ",CALC2223!K12) | F13: =CONCATENATE(CALC2223!M12," ",CALC2223!O12," ",CALC2223!Q12) | G13: =CONCATENATE(CALC2223!S12," ",CALC2223!U12," ",CALC2223!W12) | H13: =CONCATENATE(CALC2223!Y12," ",CALC2223!AA12," ",CALC2223!AC12) | I13: =CONCATENATE(CALC2223!AE12," ",CALC2223!AG12," ",CALC2223!AI12) | J13: =CONCATENATE(CALC2223!AK12," ",CALC2223!AM12," ",CALC2223!AO12) -> mentoren#1/ Claudia Visser over signaleren HB leerlingen | K13: =CONCATENATE(CALC2223!AQ12," ",CALC2223!AS12," ",CALC2223!AU12," ",CALC2223!AW12) | L13: =IF(C13<TODAY(),"verleden","actueel") -> verleden | N13: =OR(VALUE(CALC2223!B12)>VALUE(LASTV),VALUE(CALC2223!D12)>VALUE(LASTV),VALUE(CALC2223!F12)>VALUE(LASTV)) -> FALSE | O13: =OR(VALUE(CALC2223!H12)>VALUE(LASTV),VALUE(CALC2223!J12)>VALUE(LASTV),VALUE(CALC2223!L12)>VALUE(LASTV)) -> FALSE | P13: =OR(VALUE(CALC2223!N12)>VALUE(LASTV),VALUE(CALC2223!P12)>VALUE(LASTV),VALUE(CALC2223!R12)>VALUE(LASTV)) -> FALSE | Q13: =OR(VALUE(CALC2223!T12)>VALUE(LASTV),VALUE(CALC2223!V12)>VALUE(LASTV),VALUE(CALC2223!X12)>VALUE(LASTV)) -> FALSE | R13: =OR(VALUE(CALC2223!Z12)>VALUE(LASTV),VALUE(CALC2223!AB12)>VALUE(LASTV),VALUE(CALC2223!AD12)>VALUE(LASTV)) -> FALSE | S13: =OR(VALUE(CALC2223!AF12)>VALUE(LASTV),VALUE(CALC2223!AH12)>VALUE(LASTV),VALUE(CALC2223!AJ12)>VALUE(LASTV)) -> FALSE | T13: =OR(VALUE(CALC2223!AL12)>VALUE(LASTV),VALUE(CALC2223!AN12)>VALUE(LASTV),VALUE(CALC2223!AP12)>VALUE(LASTV)) -> FALSE | U13: =OR(VALUE(CALC2223!AR12)>VALUE(LASTV),VALUE(CALC2223!AT12)>VALUE(LASTV),VALUE(CALC2223!AV12)>VALUE(LASTV)) -> FALSE
B14: vr | C14: 45912 | D14: =CONCATENATE(CALC2223!A13," ",CALC2223!C13," ",CALC2223!E13) | E14: =CONCATENATE(CALC2223!G13," ",CALC2223!I13," ",CALC2223!K13) | F14: =CONCATENATE(CALC2223!M13," ",CALC2223!O13," ",CALC2223!Q13) | G14: =CONCATENATE(CALC2223!S13," ",CALC2223!U13," ",CALC2223!W13) | H14: =CONCATENATE(CALC2223!Y13," ",CALC2223!AA13," ",CALC2223!AC13) -> opgave herkansing ANW | I14: =CONCATENATE(CALC2223!AE13," ",CALC2223!AG13," ",CALC2223!AI13) -> herkansen (geen les) | J14: =CONCATENATE(CALC2223!AK13," ",CALC2223!AM13," ",CALC2223!AO13) | K14: =CONCATENATE(CALC2223!AQ13," ",CALC2223!AS13," ",CALC2223!AU13," ",CALC2223!AW13) | L14: =IF(C14<TODAY(),"verleden","actueel") -> verleden | N14: =OR(VALUE(CALC2223!B13)>VALUE(LASTV),VALUE(CALC2223!D13)>VALUE(LASTV),VALUE(CALC2223!F13)>VALUE(LASTV)) -> FALSE | O14: =OR(VALUE(CALC2223!H13)>VALUE(LASTV),VALUE(CALC2223!J13)>VALUE(LASTV),VALUE(CALC2223!L13)>VALUE(LASTV)) -> FALSE | P14: =OR(VALUE(CALC2223!N13)>VALUE(LASTV),VALUE(CALC2223!P13)>VALUE(LASTV),VALUE(CALC2223!R13)>VALUE(LASTV)) -> FALSE | Q14: =OR(VALUE(CALC2223!T13)>VALUE(LASTV),VALUE(CALC2223!V13)>VALUE(LASTV),VALUE(CALC2223!X13)>VALUE(LASTV)) -> FALSE | R14: =OR(VALUE(CALC2223!Z13)>VALUE(LASTV),VALUE(CALC2223!AB13)>VALUE(LASTV),VALUE(CALC2223!AD13)>VALUE(LASTV)) -> FALSE | S14: =OR(VALUE(CALC2223!AF13)>VALUE(LASTV),VALUE(CALC2223!AH13)>VALUE(LASTV),VALUE(CALC2223!AJ13)>VALUE(LASTV)) -> FALSE | T14: =OR(VALUE(CALC2223!AL13)>VALUE(LASTV),VALUE(CALC2223!AN13)>VALUE(LASTV),VALUE(CALC2223!AP13)>VALUE(LASTV)) -> FALSE | U14: =OR(VALUE(CALC2223!AR13)>VALUE(LASTV),VALUE(CALC2223!AT13)>VALUE(LASTV),VALUE(CALC2223!AV13)>VALUE(LASTV)) -> FALSE
B15: za | C15: 45913 | D15: =CONCATENATE(CALC2223!A14," ",CALC2223!C14," ",CALC2223!E14) | E15: =CONCATENATE(CALC2223!G14," ",CALC2223!I14," ",CALC2223!K14) | F15: =CONCATENATE(CALC2223!M14," ",CALC2223!O14," ",CALC2223!Q14) | G15: =CONCATENATE(CALC2223!S14," ",CALC2223!U14," ",CALC2223!W14) | H15: =CONCATENATE(CALC2223!Y14," ",CALC2223!AA14," ",CALC2223!AC14) | I15: =CONCATENATE(CALC2223!AE14," ",CALC2223!AG14," ",CALC2223!AI14) | J15: =CONCATENATE(CALC2223!AK14," ",CALC2223!AM14," ",CALC2223!AO14) | K15: =CONCATENATE(CALC2223!AQ14," ",CALC2223!AS14," ",CALC2223!AU14," ",CALC2223!AW14) | L15: =IF(C15<TODAY(),"verleden","actueel") -> verleden | N15: =OR(VALUE(CALC2223!B14)>VALUE(LASTV),VALUE(CALC2223!D14)>VALUE(LASTV),VALUE(CALC2223!F14)>VALUE(LASTV)) -> FALSE | O15: =OR(VALUE(CALC2223!H14)>VALUE(LASTV),VALUE(CALC2223!J14)>VALUE(LASTV),VALUE(CALC2223!L14)>VALUE(LASTV)) -> FALSE | P15: =OR(VALUE(CALC2223!N14)>VALUE(LASTV),VALUE(CALC2223!P14)>VALUE(LASTV),VALUE(CALC2223!R14)>VALUE(LASTV)) -> FALSE | Q15: =OR(VALUE(CALC2223!T14)>VALUE(LASTV),VALUE(CALC2223!V14)>VALUE(LASTV),VALUE(CALC2223!X14)>VALUE(LASTV)) -> FALSE | R15: =OR(VALUE(CALC2223!Z14)>VALUE(LASTV),VALUE(CALC2223!AB14)>VALUE(LASTV),VALUE(CALC2223!AD14)>VALUE(LASTV)) -> FALSE | S15: =OR(VALUE(CALC2223!AF14)>VALUE(LASTV),VALUE(CALC2223!AH14)>VALUE(LASTV),VALUE(CALC2223!AJ14)>VALUE(LASTV)) -> FALSE | T15: =OR(VALUE(CALC2223!AL14)>VALUE(LASTV),VALUE(CALC2223!AN14)>VALUE(LASTV),VALUE(CALC2223!AP14)>VALUE(LASTV)) -> FALSE | U15: =OR(VALUE(CALC2223!AR14)>VALUE(LASTV),VALUE(CALC2223!AT14)>VALUE(LASTV),VALUE(CALC2223!AV14)>VALUE(LASTV)) -> FALSE
B16: zo | C16: 45914 | D16: =CONCATENATE(CALC2223!A15," ",CALC2223!C15," ",CALC2223!E15) | E16: =CONCATENATE(CALC2223!G15," ",CALC2223!I15," ",CALC2223!K15) | F16: =CONCATENATE(CALC2223!M15," ",CALC2223!O15," ",CALC2223!Q15) | G16: =CONCATENATE(CALC2223!S15," ",CALC2223!U15," ",CALC2223!W15) | H16: =CONCATENATE(CALC2223!Y15," ",CALC2223!AA15," ",CALC2223!AC15) | I16: =CONCATENATE(CALC2223!AE15," ",CALC2223!AG15," ",CALC2223!AI15) | J16: =CONCATENATE(CALC2223!AK15," ",CALC2223!AM15," ",CALC2223!AO15) | K16: =CONCATENATE(CALC2223!AQ15," ",CALC2223!AS15," ",CALC2223!AU15," ",CALC2223!AW15) | L16: =IF(C16<TODAY(),"verleden","actueel") -> verleden | N16: =OR(VALUE(CALC2223!B15)>VALUE(LASTV),VALUE(CALC2223!D15)>VALUE(LASTV),VALUE(CALC2223!F15)>VALUE(LASTV)) -> FALSE | O16: =OR(VALUE(CALC2223!H15)>VALUE(LASTV),VALUE(CALC2223!J15)>VALUE(LASTV),VALUE(CALC2223!L15)>VALUE(LASTV)) -> FALSE | P16: =OR(VALUE(CALC2223!N15)>VALUE(LASTV),VALUE(CALC2223!P15)>VALUE(LASTV),VALUE(CALC2223!R15)>VALUE(LASTV)) -> FALSE | Q16: =OR(VALUE(CALC2223!T15)>VALUE(LASTV),VALUE(CALC2223!V15)>VALUE(LASTV),VALUE(CALC2223!X15)>VALUE(LASTV)) -> FALSE | R16: =OR(VALUE(CALC2223!Z15)>VALUE(LASTV),VALUE(CALC2223!AB15)>VALUE(LASTV),VALUE(CALC2223!AD15)>VALUE(LASTV)) -> FALSE | S16: =OR(VALUE(CALC2223!AF15)>VALUE(LASTV),VALUE(CALC2223!AH15)>VALUE(LASTV),VALUE(CALC2223!AJ15)>VALUE(LASTV)) -> FALSE | T16: =OR(VALUE(CALC2223!AL15)>VALUE(LASTV),VALUE(CALC2223!AN15)>VALUE(LASTV),VALUE(CALC2223!AP15)>VALUE(LASTV)) -> FALSE | U16: =OR(VALUE(CALC2223!AR15)>VALUE(LASTV),VALUE(CALC2223!AT15)>VALUE(LASTV),VALUE(CALC2223!AV15)>VALUE(LASTV)) -> FALSE
A17: 38 | B17: ma | C17: 45915 | D17: =CONCATENATE(CALC2223!A16," ",CALC2223!C16," ",CALC2223!E16) | E17: =CONCATENATE(CALC2223!G16," ",CALC2223!I16," ",CALC2223!K16) | F17: =CONCATENATE(CALC2223!M16," ",CALC2223!O16," ",CALC2223!Q16) | G17: =CONCATENATE(CALC2223!S16," ",CALC2223!U16," ",CALC2223!W16) | H17: =CONCATENATE(CALC2223!Y16," ",CALC2223!AA16," ",CALC2223!AC16) | I17: =CONCATENATE(CALC2223!AE16," ",CALC2223!AG16," ",CALC2223!AI16) | J17: =CONCATENATE(CALC2223!AK16," ",CALC2223!AM16," ",CALC2223!AO16) | K17: =CONCATENATE(CALC2223!AQ16," ",CALC2223!AS16," ",CALC2223!AU16," ",CALC2223!AW16) | L17: =IF(C17<TODAY(),"verleden","actueel") -> verleden | N17: =OR(VALUE(CALC2223!B16)>VALUE(LASTV),VALUE(CALC2223!D16)>VALUE(LASTV),VALUE(CALC2223!F16)>VALUE(LASTV)) -> FALSE | O17: =OR(VALUE(CALC2223!H16)>VALUE(LASTV),VALUE(CALC2223!J16)>VALUE(LASTV),VALUE(CALC2223!L16)>VALUE(LASTV)) -> FALSE | P17: =OR(VALUE(CALC2223!N16)>VALUE(LASTV),VALUE(CALC2223!P16)>VALUE(LASTV),VALUE(CALC2223!R16)>VALUE(LASTV)) -> FALSE | Q17: =OR(VALUE(CALC2223!T16)>VALUE(LASTV),VALUE(CALC2223!V16)>VALUE(LASTV),VALUE(CALC2223!X16)>VALUE(LASTV)) -> FALSE | R17: =OR(VALUE(CALC2223!Z16)>VALUE(LASTV),VALUE(CALC2223!AB16)>VALUE(LASTV),VALUE(CALC2223!AD16)>VALUE(LASTV)) -> FALSE | S17: =OR(VALUE(CALC2223!AF16)>VALUE(LASTV),VALUE(CALC2223!AH16)>VALUE(LASTV),VALUE(CALC2223!AJ16)>VALUE(LASTV)) -> FALSE | T17: =OR(VALUE(CALC2223!AL16)>VALUE(LASTV),VALUE(CALC2223!AN16)>VALUE(LASTV),VALUE(CALC2223!AP16)>VALUE(LASTV)) -> FALSE | U17: =OR(VALUE(CALC2223!AR16)>VALUE(LASTV),VALUE(CALC2223!AT16)>VALUE(LASTV),VALUE(CALC2223!AV16)>VALUE(LASTV)) -> FALSE
B18: di | C18: 45916 | D18: =CONCATENATE(CALC2223!A17," ",CALC2223!C17," ",CALC2223!E17) -> BKK ABCD | E18: =CONCATENATE(CALC2223!G17," ",CALC2223!I17," ",CALC2223!K17) | F18: =CONCATENATE(CALC2223!M17," ",CALC2223!O17," ",CALC2223!Q17) -> Team Ollie | G18: =CONCATENATE(CALC2223!S17," ",CALC2223!U17," ",CALC2223!W17) | H18: =CONCATENATE(CALC2223!Y17," ",CALC2223!AA17," ",CALC2223!AC17) | I18: =CONCATENATE(CALC2223!AE17," ",CALC2223!AG17," ",CALC2223!AI17) | J18: =CONCATENATE(CALC2223!AK17," ",CALC2223!AM17," ",CALC2223!AO17) | K18: =CONCATENATE(CALC2223!AQ17," ",CALC2223!AS17," ",CALC2223!AU17," ",CALC2223!AW17) | L18: =IF(C18<TODAY(),"verleden","actueel") -> verleden | N18: =OR(VALUE(CALC2223!B17)>VALUE(LASTV),VALUE(CALC2223!D17)>VALUE(LASTV),VALUE(CALC2223!F17)>VALUE(LASTV)) -> FALSE | O18: =OR(VALUE(CALC2223!H17)>VALUE(LASTV),VALUE(CALC2223!J17)>VALUE(LASTV),VALUE(CALC2223!L17)>VALUE(LASTV)) -> FALSE | P18: =OR(VALUE(CALC2223!N17)>VALUE(LASTV),VALUE(CALC2223!P17)>VALUE(LASTV),VALUE(CALC2223!R17)>VALUE(LASTV)) -> FALSE | Q18: =OR(VALUE(CALC2223!T17)>VALUE(LASTV),VALUE(CALC2223!V17)>VALUE(LASTV),VALUE(CALC2223!X17)>VALUE(LASTV)) -> FALSE | R18: =OR(VALUE(CALC2223!Z17)>VALUE(LASTV),VALUE(CALC2223!AB17)>VALUE(LASTV),VALUE(CALC2223!AD17)>VALUE(LASTV)) -> FALSE | S18: =OR(VALUE(CALC2223!AF17)>VALUE(LASTV),VALUE(CALC2223!AH17)>VALUE(LASTV),VALUE(CALC2223!AJ17)>VALUE(LASTV)) -> FALSE | T18: =OR(VALUE(CALC2223!AL17)>VALUE(LASTV),VALUE(CALC2223!AN17)>VALUE(LASTV),VALUE(CALC2223!AP17)>VALUE(LASTV)) -> FALSE | U18: =OR(VALUE(CALC2223!AR17)>VALUE(LASTV),VALUE(CALC2223!AT17)>VALUE(LASTV),VALUE(CALC2223!AV17)>VALUE(LASTV)) -> FALSE
B19: wo | C19: 45917 | D19: =CONCATENATE(CALC2223!A18," ",CALC2223!C18," ",CALC2223!E18) -> BKK ABCD | E19: =CONCATENATE(CALC2223!G18," ",CALC2223!I18," ",CALC2223!K18) | F19: =CONCATENATE(CALC2223!M18," ",CALC2223!O18," ",CALC2223!Q18) | G19: =CONCATENATE(CALC2223!S18," ",CALC2223!U18," ",CALC2223!W18) | H19: =CONCATENATE(CALC2223!Y18," ",CALC2223!AA18," ",CALC2223!AC18) -> herkansen ANW | I19: =CONCATENATE(CALC2223!AE18," ",CALC2223!AG18," ",CALC2223!AI18) | J19: =CONCATENATE(CALC2223!AK18," ",CALC2223!AM18," ",CALC2223!AO18) | K19: =CONCATENATE(CALC2223!AQ18," ",CALC2223!AS18," ",CALC2223!AU18," ",CALC2223!AW18) | L19: =IF(C19<TODAY(),"verleden","actueel") -> verleden | N19: =OR(VALUE(CALC2223!B18)>VALUE(LASTV),VALUE(CALC2223!D18)>VALUE(LASTV),VALUE(CALC2223!F18)>VALUE(LASTV)) -> FALSE | O19: =OR(VALUE(CALC2223!H18)>VALUE(LASTV),VALUE(CALC2223!J18)>VALUE(LASTV),VALUE(CALC2223!L18)>VALUE(LASTV)) -> FALSE | P19: =OR(VALUE(CALC2223!N18)>VALUE(LASTV),VALUE(CALC2223!P18)>VALUE(LASTV),VALUE(CALC2223!R18)>VALUE(LASTV)) -> FALSE | Q19: =OR(VALUE(CALC2223!T18)>VALUE(LASTV),VALUE(CALC2223!V18)>VALUE(LASTV),VALUE(CALC2223!X18)>VALUE(LASTV)) -> FALSE | R19: =OR(VALUE(CALC2223!Z18)>VALUE(LASTV),VALUE(CALC2223!AB18)>VALUE(LASTV),VALUE(CALC2223!AD18)>VALUE(LASTV)) -> FALSE | S19: =OR(VALUE(CALC2223!AF18)>VALUE(LASTV),VALUE(CALC2223!AH18)>VALUE(LASTV),VALUE(CALC2223!AJ18)>VALUE(LASTV)) -> FALSE | T19: =OR(VALUE(CALC2223!AL18)>VALUE(LASTV),VALUE(CALC2223!AN18)>VALUE(LASTV),VALUE(CALC2223!AP18)>VALUE(LASTV)) -> FALSE | U19: =OR(VALUE(CALC2223!AR18)>VALUE(LASTV),VALUE(CALC2223!AT18)>VALUE(LASTV),VALUE(CALC2223!AV18)>VALUE(LASTV)) -> FALSE
B20: do | C20: 45918 | D20: =CONCATENATE(CALC2223!A19," ",CALC2223!C19," ",CALC2223!E19) -> BKK ABCD | E20: =CONCATENATE(CALC2223!G19," ",CALC2223!I19," ",CALC2223!K19) | F20: =CONCATENATE(CALC2223!M19," ",CALC2223!O19," ",CALC2223!Q19) | G20: =CONCATENATE(CALC2223!S19," ",CALC2223!U19," ",CALC2223!W19) | H20: =CONCATENATE(CALC2223!Y19," ",CALC2223!AA19," ",CALC2223!AC19) | I20: =CONCATENATE(CALC2223!AE19," ",CALC2223!AG19," ",CALC2223!AI19) -> LO1:1 | J20: =CONCATENATE(CALC2223!AK19," ",CALC2223!AM19," ",CALC2223!AO19) -> commissies#1 verpleegkundige | K20: =CONCATENATE(CALC2223!AQ19," ",CALC2223!AS19," ",CALC2223!AU19," ",CALC2223!AW19) | L20: =IF(C20<TODAY(),"verleden","actueel") -> verleden | N20: =OR(VALUE(CALC2223!B19)>VALUE(LASTV),VALUE(CALC2223!D19)>VALUE(LASTV),VALUE(CALC2223!F19)>VALUE(LASTV)) -> FALSE | O20: =OR(VALUE(CALC2223!H19)>VALUE(LASTV),VALUE(CALC2223!J19)>VALUE(LASTV),VALUE(CALC2223!L19)>VALUE(LASTV)) -> FALSE | P20: =OR(VALUE(CALC2223!N19)>VALUE(LASTV),VALUE(CALC2223!P19)>VALUE(LASTV),VALUE(CALC2223!R19)>VALUE(LASTV)) -> FALSE | Q20: =OR(VALUE(CALC2223!T19)>VALUE(LASTV),VALUE(CALC2223!V19)>VALUE(LASTV),VALUE(CALC2223!X19)>VALUE(LASTV)) -> FALSE | R20: =OR(VALUE(CALC2223!Z19)>VALUE(LASTV),VALUE(CALC2223!AB19)>VALUE(LASTV),VALUE(CALC2223!AD19)>VALUE(LASTV)) -> FALSE | S20: =OR(VALUE(CALC2223!AF19)>VALUE(LASTV),VALUE(CALC2223!AH19)>VALUE(LASTV),VALUE(CALC2223!AJ19)>VALUE(LASTV)) -> FALSE | T20: =OR(VALUE(CALC2223!AL19)>VALUE(LASTV),VALUE(CALC2223!AN19)>VALUE(LASTV),VALUE(CALC2223!AP19)>VALUE(LASTV)) -> FALSE | U20: =OR(VALUE(CALC2223!AR19)>VALUE(LASTV),VALUE(CALC2223!AT19)>VALUE(LASTV),VALUE(CALC2223!AV19)>VALUE(LASTV)) -> FALSE
B21: vr | C21: 45919 | D21: =CONCATENATE(CALC2223!A20," ",CALC2223!C20," ",CALC2223!E20) -> BKK ABCD | E21: =CONCATENATE(CALC2223!G20," ",CALC2223!I20," ",CALC2223!K20) | F21: =CONCATENATE(CALC2223!M20," ",CALC2223!O20," ",CALC2223!Q20) | G21: =CONCATENATE(CALC2223!S20," ",CALC2223!U20," ",CALC2223!W20) | H21: =CONCATENATE(CALC2223!Y20," ",CALC2223!AA20," ",CALC2223!AC20) | I21: =CONCATENATE(CALC2223!AE20," ",CALC2223!AG20," ",CALC2223!AI20) | J21: =CONCATENATE(CALC2223!AK20," ",CALC2223!AM20," ",CALC2223!AO20) | K21: =CONCATENATE(CALC2223!AQ20," ",CALC2223!AS20," ",CALC2223!AU20," ",CALC2223!AW20) | L21: =IF(C21<TODAY(),"verleden","actueel") -> verleden | N21: =OR(VALUE(CALC2223!B20)>VALUE(LASTV),VALUE(CALC2223!D20)>VALUE(LASTV),VALUE(CALC2223!F20)>VALUE(LASTV)) -> FALSE | O21: =OR(VALUE(CALC2223!H20)>VALUE(LASTV),VALUE(CALC2223!J20)>VALUE(LASTV),VALUE(CALC2223!L20)>VALUE(LASTV)) -> FALSE | P21: =OR(VALUE(CALC2223!N20)>VALUE(LASTV),VALUE(CALC2223!P20)>VALUE(LASTV),VALUE(CALC2223!R20)>VALUE(LASTV)) -> FALSE | Q21: =OR(VALUE(CALC2223!T20)>VALUE(LASTV),VALUE(CALC2223!V20)>VALUE(LASTV),VALUE(CALC2223!X20)>VALUE(LASTV)) -> FALSE | R21: =OR(VALUE(CALC2223!Z20)>VALUE(LASTV),VALUE(CALC2223!AB20)>VALUE(LASTV),VALUE(CALC2223!AD20)>VALUE(LASTV)) -> FALSE | S21: =OR(VALUE(CALC2223!AF20)>VALUE(LASTV),VALUE(CALC2223!AH20)>VALUE(LASTV),VALUE(CALC2223!AJ20)>VALUE(LASTV)) -> FALSE | T21: =OR(VALUE(CALC2223!AL20)>VALUE(LASTV),VALUE(CALC2223!AN20)>VALUE(LASTV),VALUE(CALC2223!AP20)>VALUE(LASTV)) -> FALSE | U21: =OR(VALUE(CALC2223!AR20)>VALUE(LASTV),VALUE(CALC2223!AT20)>VALUE(LASTV),VALUE(CALC2223!AV20)>VALUE(LASTV)) -> FALSE
B22: za | C22: 45920 | D22: =CONCATENATE(CALC2223!A21," ",CALC2223!C21," ",CALC2223!E21) | E22: =CONCATENATE(CALC2223!G21," ",CALC2223!I21," ",CALC2223!K21) | F22: =CONCATENATE(CALC2223!M21," ",CALC2223!O21," ",CALC2223!Q21) | G22: =CONCATENATE(CALC2223!S21," ",CALC2223!U21," ",CALC2223!W21) | H22: =CONCATENATE(CALC2223!Y21," ",CALC2223!AA21," ",CALC2223!AC21) | I22: =CONCATENATE(CALC2223!AE21," ",CALC2223!AG21," ",CALC2223!AI21) | J22: =CONCATENATE(CALC2223!AK21," ",CALC2223!AM21," ",CALC2223!AO21) | K22: =CONCATENATE(CALC2223!AQ21," ",CALC2223!AS21," ",CALC2223!AU21," ",CALC2223!AW21) | L22: =IF(C22<TODAY(),"verleden","actueel") -> verleden | N22: =OR(VALUE(CALC2223!B21)>VALUE(LASTV),VALUE(CALC2223!D21)>VALUE(LASTV),VALUE(CALC2223!F21)>VALUE(LASTV)) -> FALSE | O22: =OR(VALUE(CALC2223!H21)>VALUE(LASTV),VALUE(CALC2223!J21)>VALUE(LASTV),VALUE(CALC2223!L21)>VALUE(LASTV)) -> FALSE | P22: =OR(VALUE(CALC2223!N21)>VALUE(LASTV),VALUE(CALC2223!P21)>VALUE(LASTV),VALUE(CALC2223!R21)>VALUE(LASTV)) -> FALSE | Q22: =OR(VALUE(CALC2223!T21)>VALUE(LASTV),VALUE(CALC2223!V21)>VALUE(LASTV),VALUE(CALC2223!X21)>VALUE(LASTV)) -> FALSE | R22: =OR(VALUE(CALC2223!Z21)>VALUE(LASTV),VALUE(CALC2223!AB21)>VALUE(LASTV),VALUE(CALC2223!AD21)>VALUE(LASTV)) -> FALSE | S22: =OR(VALUE(CALC2223!AF21)>VALUE(LASTV),VALUE(CALC2223!AH21)>VALUE(LASTV),VALUE(CALC2223!AJ21)>VALUE(LASTV)) -> FALSE | T22: =OR(VALUE(CALC2223!AL21)>VALUE(LASTV),VALUE(CALC2223!AN21)>VALUE(LASTV),VALUE(CALC2223!AP21)>VALUE(LASTV)) -> FALSE | U22: =OR(VALUE(CALC2223!AR21)>VALUE(LASTV),VALUE(CALC2223!AT21)>VALUE(LASTV),VALUE(CALC2223!AV21)>VALUE(LASTV)) -> FALSE
B23: zo | C23: 45921 | D23: =CONCATENATE(CALC2223!A22," ",CALC2223!C22," ",CALC2223!E22) | E23: =CONCATENATE(CALC2223!G22," ",CALC2223!I22," ",CALC2223!K22) | F23: =CONCATENATE(CALC2223!M22," ",CALC2223!O22," ",CALC2223!Q22) | G23: =CONCATENATE(CALC2223!S22," ",CALC2223!U22," ",CALC2223!W22) | H23: =CONCATENATE(CALC2223!Y22," ",CALC2223!AA22," ",CALC2223!AC22) | I23: =CONCATENATE(CALC2223!AE22," ",CALC2223!AG22," ",CALC2223!AI22) | J23: =CONCATENATE(CALC2223!AK22," ",CALC2223!AM22," ",CALC2223!AO22) | K23: =CONCATENATE(CALC2223!AQ22," ",CALC2223!AS22," ",CALC2223!AU22," ",CALC2223!AW22) | L23: =IF(C23<TODAY(),"verleden","actueel") -> verleden | N23: =OR(VALUE(CALC2223!B22)>VALUE(LASTV),VALUE(CALC2223!D22)>VALUE(LASTV),VALUE(CALC2223!F22)>VALUE(LASTV)) -> FALSE | O23: =OR(VALUE(CALC2223!H22)>VALUE(LASTV),VALUE(CALC2223!J22)>VALUE(LASTV),VALUE(CALC2223!L22)>VALUE(LASTV)) -> FALSE | P23: =OR(VALUE(CALC2223!N22)>VALUE(LASTV),VALUE(CALC2223!P22)>VALUE(LASTV),VALUE(CALC2223!R22)>VALUE(LASTV)) -> FALSE | Q23: =OR(VALUE(CALC2223!T22)>VALUE(LASTV),VALUE(CALC2223!V22)>VALUE(LASTV),VALUE(CALC2223!X22)>VALUE(LASTV)) -> FALSE | R23: =OR(VALUE(CALC2223!Z22)>VALUE(LASTV),VALUE(CALC2223!AB22)>VALUE(LASTV),VALUE(CALC2223!AD22)>VALUE(LASTV)) -> FALSE | S23: =OR(VALUE(CALC2223!AF22)>VALUE(LASTV),VALUE(CALC2223!AH22)>VALUE(LASTV),VALUE(CALC2223!AJ22)>VALUE(LASTV)) -> FALSE | T23: =OR(VALUE(CALC2223!AL22)>VALUE(LASTV),VALUE(CALC2223!AN22)>VALUE(LASTV),VALUE(CALC2223!AP22)>VALUE(LASTV)) -> FALSE | U23: =OR(VALUE(CALC2223!AR22)>VALUE(LASTV),VALUE(CALC2223!AT22)>VALUE(LASTV),VALUE(CALC2223!AV22)>VALUE(LASTV)) -> FALSE
A24: 39 | B24: ma | C24: 45922 | D24: =CONCATENATE(CALC2223!A23," ",CALC2223!C23," ",CALC2223!E23) | E24: =CONCATENATE(CALC2223!G23," ",CALC2223!I23," ",CALC2223!K23) | F24: =CONCATENATE(CALC2223!M23," ",CALC2223!O23," ",CALC2223!Q23) | G24: =CONCATENATE(CALC2223!S23," ",CALC2223!U23," ",CALC2223!W23) | H24: =CONCATENATE(CALC2223!Y23," ",CALC2223!AA23," ",CALC2223!AC23) | I24: =CONCATENATE(CALC2223!AE23," ",CALC2223!AG23," ",CALC2223!AI23) | J24: =CONCATENATE(CALC2223!AK23," ",CALC2223!AM23," ",CALC2223!AO23) | K24: =CONCATENATE(CALC2223!AQ23," ",CALC2223!AS23," ",CALC2223!AU23," ",CALC2223!AW23) | L24: =IF(C24<TODAY(),"verleden","actueel") -> verleden | N24: =OR(VALUE(CALC2223!B23)>VALUE(LASTV),VALUE(CALC2223!D23)>VALUE(LASTV),VALUE(CALC2223!F23)>VALUE(LASTV)) -> FALSE | O24: =OR(VALUE(CALC2223!H23)>VALUE(LASTV),VALUE(CALC2223!J23)>VALUE(LASTV),VALUE(CALC2223!L23)>VALUE(LASTV)) -> FALSE | P24: =OR(VALUE(CALC2223!N23)>VALUE(LASTV),VALUE(CALC2223!P23)>VALUE(LASTV),VALUE(CALC2223!R23)>VALUE(LASTV)) -> FALSE | Q24: =OR(VALUE(CALC2223!T23)>VALUE(LASTV),VALUE(CALC2223!V23)>VALUE(LASTV),VALUE(CALC2223!X23)>VALUE(LASTV)) -> FALSE | R24: =OR(VALUE(CALC2223!Z23)>VALUE(LASTV),VALUE(CALC2223!AB23)>VALUE(LASTV),VALUE(CALC2223!AD23)>VALUE(LASTV)) -> FALSE | S24: =OR(VALUE(CALC2223!AF23)>VALUE(LASTV),VALUE(CALC2223!AH23)>VALUE(LASTV),VALUE(CALC2223!AJ23)>VALUE(LASTV)) -> FALSE | T24: =OR(VALUE(CALC2223!AL23)>VALUE(LASTV),VALUE(CALC2223!AN23)>VALUE(LASTV),VALUE(CALC2223!AP23)>VALUE(LASTV)) -> FALSE | U24: =OR(VALUE(CALC2223!AR23)>VALUE(LASTV),VALUE(CALC2223!AT23)>VALUE(LASTV),VALUE(CALC2223!AV23)>VALUE(LASTV)) -> FALSE
B25: di | C25: 45923 | D25: =CONCATENATE(CALC2223!A24," ",CALC2223!C24," ",CALC2223!E24) -> BKK EFG | E25: =CONCATENATE(CALC2223!G24," ",CALC2223!I24," ",CALC2223!K24) | F25: =CONCATENATE(CALC2223!M24," ",CALC2223!O24," ",CALC2223!Q24) | G25: =CONCATENATE(CALC2223!S24," ",CALC2223!U24," ",CALC2223!W24) | H25: =CONCATENATE(CALC2223!Y24," ",CALC2223!AA24," ",CALC2223!AC24) -> inh rep EN inh rep SK | I25: =CONCATENATE(CALC2223!AE24," ",CALC2223!AG24," ",CALC2223!AI24) | J25: =CONCATENATE(CALC2223!AK24," ",CALC2223!AM24," ",CALC2223!AO24) | K25: =CONCATENATE(CALC2223!AQ24," ",CALC2223!AS24," ",CALC2223!AU24," ",CALC2223!AW24) | L25: =IF(C25<TODAY(),"verleden","actueel") -> verleden | N25: =OR(VALUE(CALC2223!B24)>VALUE(LASTV),VALUE(CALC2223!D24)>VALUE(LASTV),VALUE(CALC2223!F24)>VALUE(LASTV)) -> FALSE | O25: =OR(VALUE(CALC2223!H24)>VALUE(LASTV),VALUE(CALC2223!J24)>VALUE(LASTV),VALUE(CALC2223!L24)>VALUE(LASTV)) -> FALSE | P25: =OR(VALUE(CALC2223!N24)>VALUE(LASTV),VALUE(CALC2223!P24)>VALUE(LASTV),VALUE(CALC2223!R24)>VALUE(LASTV)) -> FALSE | Q25: =OR(VALUE(CALC2223!T24)>VALUE(LASTV),VALUE(CALC2223!V24)>VALUE(LASTV),VALUE(CALC2223!X24)>VALUE(LASTV)) -> FALSE | R25: =OR(VALUE(CALC2223!Z24)>VALUE(LASTV),VALUE(CALC2223!AB24)>VALUE(LASTV),VALUE(CALC2223!AD24)>VALUE(LASTV)) -> FALSE | S25: =OR(VALUE(CALC2223!AF24)>VALUE(LASTV),VALUE(CALC2223!AH24)>VALUE(LASTV),VALUE(CALC2223!AJ24)>VALUE(LASTV)) -> FALSE | T25: =OR(VALUE(CALC2223!AL24)>VALUE(LASTV),VALUE(CALC2223!AN24)>VALUE(LASTV),VALUE(CALC2223!AP24)>VALUE(LASTV)) -> FALSE | U25: =OR(VALUE(CALC2223!AR24)>VALUE(LASTV),VALUE(CALC2223!AT24)>VALUE(LASTV),VALUE(CALC2223!AV24)>VALUE(LASTV)) -> FALSE
B26: wo | C26: 45924 | D26: =CONCATENATE(CALC2223!A25," ",CALC2223!C25," ",CALC2223!E25) -> BKK EFG | E26: =CONCATENATE(CALC2223!G25," ",CALC2223!I25," ",CALC2223!K25) | F26: =CONCATENATE(CALC2223!M25," ",CALC2223!O25," ",CALC2223!Q25) | G26: =CONCATENATE(CALC2223!S25," ",CALC2223!U25," ",CALC2223!W25) | H26: =CONCATENATE(CALC2223!Y25," ",CALC2223!AA25," ",CALC2223!AC25) | I26: =CONCATENATE(CALC2223!AE25," ",CALC2223!AG25," ",CALC2223!AI25) | J26: =CONCATENATE(CALC2223!AK25," ",CALC2223!AM25," ",CALC2223!AO25) | K26: =CONCATENATE(CALC2223!AQ25," ",CALC2223!AS25," ",CALC2223!AU25," ",CALC2223!AW25) | L26: =IF(C26<TODAY(),"verleden","actueel") -> verleden | N26: =OR(VALUE(CALC2223!B25)>VALUE(LASTV),VALUE(CALC2223!D25)>VALUE(LASTV),VALUE(CALC2223!F25)>VALUE(LASTV)) -> FALSE | O26: =OR(VALUE(CALC2223!H25)>VALUE(LASTV),VALUE(CALC2223!J25)>VALUE(LASTV),VALUE(CALC2223!L25)>VALUE(LASTV)) -> FALSE | P26: =OR(VALUE(CALC2223!N25)>VALUE(LASTV),VALUE(CALC2223!P25)>VALUE(LASTV),VALUE(CALC2223!R25)>VALUE(LASTV)) -> FALSE | Q26: =OR(VALUE(CALC2223!T25)>VALUE(LASTV),VALUE(CALC2223!V25)>VALUE(LASTV),VALUE(CALC2223!X25)>VALUE(LASTV)) -> FALSE | R26: =OR(VALUE(CALC2223!Z25)>VALUE(LASTV),VALUE(CALC2223!AB25)>VALUE(LASTV),VALUE(CALC2223!AD25)>VALUE(LASTV)) -> FALSE | S26: =OR(VALUE(CALC2223!AF25)>VALUE(LASTV),VALUE(CALC2223!AH25)>VALUE(LASTV),VALUE(CALC2223!AJ25)>VALUE(LASTV)) -> FALSE | T26: =OR(VALUE(CALC2223!AL25)>VALUE(LASTV),VALUE(CALC2223!AN25)>VALUE(LASTV),VALUE(CALC2223!AP25)>VALUE(LASTV)) -> FALSE | U26: =OR(VALUE(CALC2223!AR25)>VALUE(LASTV),VALUE(CALC2223!AT25)>VALUE(LASTV),VALUE(CALC2223!AV25)>VALUE(LASTV)) -> FALSE
B27: do | C27: 45925 | D27: =CONCATENATE(CALC2223!A26," ",CALC2223!C26," ",CALC2223!E26) -> BKK EFG | E27: =CONCATENATE(CALC2223!G26," ",CALC2223!I26," ",CALC2223!K26) | F27: =CONCATENATE(CALC2223!M26," ",CALC2223!O26," ",CALC2223!Q26) | G27: =CONCATENATE(CALC2223!S26," ",CALC2223!U26," ",CALC2223!W26) | H27: =CONCATENATE(CALC2223!Y26," ",CALC2223!AA26," ",CALC2223!AC26) | I27: =CONCATENATE(CALC2223!AE26," ",CALC2223!AG26," ",CALC2223!AI26) -> LO1:2 | J27: =CONCATENATE(CALC2223!AK26," ",CALC2223!AM26," ",CALC2223!AO26) -> commissies#2/MR#1 | K27: =CONCATENATE(CALC2223!AQ26," ",CALC2223!AS26," ",CALC2223!AU26," ",CALC2223!AW26) | L27: =IF(C27<TODAY(),"verleden","actueel") -> verleden | N27: =OR(VALUE(CALC2223!B26)>VALUE(LASTV),VALUE(CALC2223!D26)>VALUE(LASTV),VALUE(CALC2223!F26)>VALUE(LASTV)) -> FALSE | O27: =OR(VALUE(CALC2223!H26)>VALUE(LASTV),VALUE(CALC2223!J26)>VALUE(LASTV),VALUE(CALC2223!L26)>VALUE(LASTV)) -> FALSE | P27: =OR(VALUE(CALC2223!N26)>VALUE(LASTV),VALUE(CALC2223!P26)>VALUE(LASTV),VALUE(CALC2223!R26)>VALUE(LASTV)) -> FALSE | Q27: =OR(VALUE(CALC2223!T26)>VALUE(LASTV),VALUE(CALC2223!V26)>VALUE(LASTV),VALUE(CALC2223!X26)>VALUE(LASTV)) -> FALSE | R27: =OR(VALUE(CALC2223!Z26)>VALUE(LASTV),VALUE(CALC2223!AB26)>VALUE(LASTV),VALUE(CALC2223!AD26)>VALUE(LASTV)) -> FALSE | S27: =OR(VALUE(CALC2223!AF26)>VALUE(LASTV),VALUE(CALC2223!AH26)>VALUE(LASTV),VALUE(CALC2223!AJ26)>VALUE(LASTV)) -> FALSE | T27: =OR(VALUE(CALC2223!AL26)>VALUE(LASTV),VALUE(CALC2223!AN26)>VALUE(LASTV),VALUE(CALC2223!AP26)>VALUE(LASTV)) -> FALSE | U27: =OR(VALUE(CALC2223!AR26)>VALUE(LASTV),VALUE(CALC2223!AT26)>VALUE(LASTV),VALUE(CALC2223!AV26)>VALUE(LASTV)) -> FALSE
B28: vr | C28: 45926 | D28: =CONCATENATE(CALC2223!A27," ",CALC2223!C27," ",CALC2223!E27) -> BKK EFG | E28: =CONCATENATE(CALC2223!G27," ",CALC2223!I27," ",CALC2223!K27) | F28: =CONCATENATE(CALC2223!M27," ",CALC2223!O27," ",CALC2223!Q27) | G28: =CONCATENATE(CALC2223!S27," ",CALC2223!U27," ",CALC2223!W27) | H28: =CONCATENATE(CALC2223!Y27," ",CALC2223!AA27," ",CALC2223!AC27) | I28: =CONCATENATE(CALC2223!AE27," ",CALC2223!AG27," ",CALC2223!AI27) | J28: =CONCATENATE(CALC2223!AK27," ",CALC2223!AM27," ",CALC2223!AO27) | K28: =CONCATENATE(CALC2223!AQ27," ",CALC2223!AS27," ",CALC2223!AU27," ",CALC2223!AW27) | L28: =IF(C28<TODAY(),"verleden","actueel") -> verleden | N28: =OR(VALUE(CALC2223!B27)>VALUE(LASTV),VALUE(CALC2223!D27)>VALUE(LASTV),VALUE(CALC2223!F27)>VALUE(LASTV)) -> FALSE | O28: =OR(VALUE(CALC2223!H27)>VALUE(LASTV),VALUE(CALC2223!J27)>VALUE(LASTV),VALUE(CALC2223!L27)>VALUE(LASTV)) -> FALSE | P28: =OR(VALUE(CALC2223!N27)>VALUE(LASTV),VALUE(CALC2223!P27)>VALUE(LASTV),VALUE(CALC2223!R27)>VALUE(LASTV)) -> FALSE | Q28: =OR(VALUE(CALC2223!T27)>VALUE(LASTV),VALUE(CALC2223!V27)>VALUE(LASTV),VALUE(CALC2223!X27)>VALUE(LASTV)) -> FALSE | R28: =OR(VALUE(CALC2223!Z27)>VALUE(LASTV),VALUE(CALC2223!AB27)>VALUE(LASTV),VALUE(CALC2223!AD27)>VALUE(LASTV)) -> FALSE | S28: =OR(VALUE(CALC2223!AF27)>VALUE(LASTV),VALUE(CALC2223!AH27)>VALUE(LASTV),VALUE(CALC2223!AJ27)>VALUE(LASTV)) -> FALSE | T28: =OR(VALUE(CALC2223!AL27)>VALUE(LASTV),VALUE(CALC2223!AN27)>VALUE(LASTV),VALUE(CALC2223!AP27)>VALUE(LASTV)) -> FALSE | U28: =OR(VALUE(CALC2223!AR27)>VALUE(LASTV),VALUE(CALC2223!AT27)>VALUE(LASTV),VALUE(CALC2223!AV27)>VALUE(LASTV)) -> FALSE
B29: za | C29: 45927 | D29: =CONCATENATE(CALC2223!A28," ",CALC2223!C28," ",CALC2223!E28) | E29: =CONCATENATE(CALC2223!G28," ",CALC2223!I28," ",CALC2223!K28) | F29: =CONCATENATE(CALC2223!M28," ",CALC2223!O28," ",CALC2223!Q28) | G29: =CONCATENATE(CALC2223!S28," ",CALC2223!U28," ",CALC2223!W28) | H29: =CONCATENATE(CALC2223!Y28," ",CALC2223!AA28," ",CALC2223!AC28) | I29: =CONCATENATE(CALC2223!AE28," ",CALC2223!AG28," ",CALC2223!AI28) | J29: =CONCATENATE(CALC2223!AK28," ",CALC2223!AM28," ",CALC2223!AO28) | K29: =CONCATENATE(CALC2223!AQ28," ",CALC2223!AS28," ",CALC2223!AU28," ",CALC2223!AW28) | L29: =IF(C29<TODAY(),"verleden","actueel") -> verleden | N29: =OR(VALUE(CALC2223!B28)>VALUE(LASTV),VALUE(CALC2223!D28)>VALUE(LASTV),VALUE(CALC2223!F28)>VALUE(LASTV)) -> FALSE | O29: =OR(VALUE(CALC2223!H28)>VALUE(LASTV),VALUE(CALC2223!J28)>VALUE(LASTV),VALUE(CALC2223!L28)>VALUE(LASTV)) -> FALSE | P29: =OR(VALUE(CALC2223!N28)>VALUE(LASTV),VALUE(CALC2223!P28)>VALUE(LASTV),VALUE(CALC2223!R28)>VALUE(LASTV)) -> FALSE | Q29: =OR(VALUE(CALC2223!T28)>VALUE(LASTV),VALUE(CALC2223!V28)>VALUE(LASTV),VALUE(CALC2223!X28)>VALUE(LASTV)) -> FALSE | R29: =OR(VALUE(CALC2223!Z28)>VALUE(LASTV),VALUE(CALC2223!AB28)>VALUE(LASTV),VALUE(CALC2223!AD28)>VALUE(LASTV)) -> FALSE | S29: =OR(VALUE(CALC2223!AF28)>VALUE(LASTV),VALUE(CALC2223!AH28)>VALUE(LASTV),VALUE(CALC2223!AJ28)>VALUE(LASTV)) -> FALSE | T29: =OR(VALUE(CALC2223!AL28)>VALUE(LASTV),VALUE(CALC2223!AN28)>VALUE(LASTV),VALUE(CALC2223!AP28)>VALUE(LASTV)) -> FALSE | U29: =OR(VALUE(CALC2223!AR28)>VALUE(LASTV),VALUE(CALC2223!AT28)>VALUE(LASTV),VALUE(CALC2223!AV28)>VALUE(LASTV)) -> FALSE
B30: zo | C30: 45928 | D30: =CONCATENATE(CALC2223!A29," ",CALC2223!C29," ",CALC2223!E29) | E30: =CONCATENATE(CALC2223!G29," ",CALC2223!I29," ",CALC2223!K29) | F30: =CONCATENATE(CALC2223!M29," ",CALC2223!O29," ",CALC2223!Q29) | G30: =CONCATENATE(CALC2223!S29," ",CALC2223!U29," ",CALC2223!W29) | H30: =CONCATENATE(CALC2223!Y29," ",CALC2223!AA29," ",CALC2223!AC29) | I30: =CONCATENATE(CALC2223!AE29," ",CALC2223!AG29," ",CALC2223!AI29) | J30: =CONCATENATE(CALC2223!AK29," ",CALC2223!AM29," ",CALC2223!AO29) | K30: =CONCATENATE(CALC2223!AQ29," ",CALC2223!AS29," ",CALC2223!AU29," ",CALC2223!AW29) | L30: =IF(C30<TODAY(),"verleden","actueel") -> verleden | N30: =OR(VALUE(CALC2223!B29)>VALUE(LASTV),VALUE(CALC2223!D29)>VALUE(LASTV),VALUE(CALC2223!F29)>VALUE(LASTV)) -> FALSE | O30: =OR(VALUE(CALC2223!H29)>VALUE(LASTV),VALUE(CALC2223!J29)>VALUE(LASTV),VALUE(CALC2223!L29)>VALUE(LASTV)) -> FALSE | P30: =OR(VALUE(CALC2223!N29)>VALUE(LASTV),VALUE(CALC2223!P29)>VALUE(LASTV),VALUE(CALC2223!R29)>VALUE(LASTV)) -> FALSE | Q30: =OR(VALUE(CALC2223!T29)>VALUE(LASTV),VALUE(CALC2223!V29)>VALUE(LASTV),VALUE(CALC2223!X29)>VALUE(LASTV)) -> FALSE | R30: =OR(VALUE(CALC2223!Z29)>VALUE(LASTV),VALUE(CALC2223!AB29)>VALUE(LASTV),VALUE(CALC2223!AD29)>VALUE(LASTV)) -> FALSE | S30: =OR(VALUE(CALC2223!AF29)>VALUE(LASTV),VALUE(CALC2223!AH29)>VALUE(LASTV),VALUE(CALC2223!AJ29)>VALUE(LASTV)) -> FALSE | T30: =OR(VALUE(CALC2223!AL29)>VALUE(LASTV),VALUE(CALC2223!AN29)>VALUE(LASTV),VALUE(CALC2223!AP29)>VALUE(LASTV)) -> FALSE | U30: =OR(VALUE(CALC2223!AR29)>VALUE(LASTV),VALUE(CALC2223!AT29)>VALUE(LASTV),VALUE(CALC2223!AV29)>VALUE(LASTV)) -> FALSE
A31: 40 | B31: ma | C31: 45929 | D31: =CONCATENATE(CALC2223!A30," ",CALC2223!C30," ",CALC2223!E30) | E31: =CONCATENATE(CALC2223!G30," ",CALC2223!I30," ",CALC2223!K30) | F31: =CONCATENATE(CALC2223!M30," ",CALC2223!O30," ",CALC2223!Q30) -> Team Ollie | G31: =CONCATENATE(CALC2223!S30," ",CALC2223!U30," ",CALC2223!W30) | H31: =CONCATENATE(CALC2223!Y30," ",CALC2223!AA30," ",CALC2223!AC30) | I31: =CONCATENATE(CALC2223!AE30," ",CALC2223!AG30," ",CALC2223!AI30) -> excursie ak | J31: =CONCATENATE(CALC2223!AK30," ",CALC2223!AM30," ",CALC2223!AO30) | K31: =CONCATENATE(CALC2223!AQ30," ",CALC2223!AS30," ",CALC2223!AU30," ",CALC2223!AW30) -> ouderavond G3 (19 u) en G6 (20 u) | L31: =IF(C31<TODAY(),"verleden","actueel") -> verleden | N31: =OR(VALUE(CALC2223!B30)>VALUE(LASTV),VALUE(CALC2223!D30)>VALUE(LASTV),VALUE(CALC2223!F30)>VALUE(LASTV)) -> FALSE | O31: =OR(VALUE(CALC2223!H30)>VALUE(LASTV),VALUE(CALC2223!J30)>VALUE(LASTV),VALUE(CALC2223!L30)>VALUE(LASTV)) -> FALSE | P31: =OR(VALUE(CALC2223!N30)>VALUE(LASTV),VALUE(CALC2223!P30)>VALUE(LASTV),VALUE(CALC2223!R30)>VALUE(LASTV)) -> FALSE | Q31: =OR(VALUE(CALC2223!T30)>VALUE(LASTV),VALUE(CALC2223!V30)>VALUE(LASTV),VALUE(CALC2223!X30)>VALUE(LASTV)) -> FALSE | R31: =OR(VALUE(CALC2223!Z30)>VALUE(LASTV),VALUE(CALC2223!AB30)>VALUE(LASTV),VALUE(CALC2223!AD30)>VALUE(LASTV)) -> FALSE | S31: =OR(VALUE(CALC2223!AF30)>VALUE(LASTV),VALUE(CALC2223!AH30)>VALUE(LASTV),VALUE(CALC2223!AJ30)>VALUE(LASTV)) -> FALSE | T31: =OR(VALUE(CALC2223!AL30)>VALUE(LASTV),VALUE(CALC2223!AN30)>VALUE(LASTV),VALUE(CALC2223!AP30)>VALUE(LASTV)) -> FALSE | U31: =OR(VALUE(CALC2223!AR30)>VALUE(LASTV),VALUE(CALC2223!AT30)>VALUE(LASTV),VALUE(CALC2223!AV30)>VALUE(LASTV)) -> FALSE
B32: di | C32: 45930 | D32: =CONCATENATE(CALC2223!A31," ",CALC2223!C31," ",CALC2223!E31) | E32: =CONCATENATE(CALC2223!G31," ",CALC2223!I31," ",CALC2223!K31) | F32: =CONCATENATE(CALC2223!M31," ",CALC2223!O31," ",CALC2223!Q31) | G32: =CONCATENATE(CALC2223!S31," ",CALC2223!U31," ",CALC2223!W31) | H32: =CONCATENATE(CALC2223!Y31," ",CALC2223!AA31," ",CALC2223!AC31) | I32: =CONCATENATE(CALC2223!AE31," ",CALC2223!AG31," ",CALC2223!AI31) | J32: =CONCATENATE(CALC2223!AK31," ",CALC2223!AM31," ",CALC2223!AO31) | K32: =CONCATENATE(CALC2223!AQ31," ",CALC2223!AS31," ",CALC2223!AU31," ",CALC2223!AW31) | L32: =IF(C32<TODAY(),"verleden","actueel") -> verleden | N32: =OR(VALUE(CALC2223!B31)>VALUE(LASTV),VALUE(CALC2223!D31)>VALUE(LASTV),VALUE(CALC2223!F31)>VALUE(LASTV)) -> FALSE | O32: =OR(VALUE(CALC2223!H31)>VALUE(LASTV),VALUE(CALC2223!J31)>VALUE(LASTV),VALUE(CALC2223!L31)>VALUE(LASTV)) -> FALSE | P32: =OR(VALUE(CALC2223!N31)>VALUE(LASTV),VALUE(CALC2223!P31)>VALUE(LASTV),VALUE(CALC2223!R31)>VALUE(LASTV)) -> FALSE | Q32: =OR(VALUE(CALC2223!T31)>VALUE(LASTV),VALUE(CALC2223!V31)>VALUE(LASTV),VALUE(CALC2223!X31)>VALUE(LASTV)) -> FALSE | R32: =OR(VALUE(CALC2223!Z31)>VALUE(LASTV),VALUE(CALC2223!AB31)>VALUE(LASTV),VALUE(CALC2223!AD31)>VALUE(LASTV)) -> FALSE | S32: =OR(VALUE(CALC2223!AF31)>VALUE(LASTV),VALUE(CALC2223!AH31)>VALUE(LASTV),VALUE(CALC2223!AJ31)>VALUE(LASTV)) -> FALSE | T32: =OR(VALUE(CALC2223!AL31)>VALUE(LASTV),VALUE(CALC2223!AN31)>VALUE(LASTV),VALUE(CALC2223!AP31)>VALUE(LASTV)) -> FALSE | U32: =OR(VALUE(CALC2223!AR31)>VALUE(LASTV),VALUE(CALC2223!AT31)>VALUE(LASTV),VALUE(CALC2223!AV31)>VALUE(LASTV)) -> FALSE
B33: wo | C33: 45931 | D33: =CONCATENATE(CALC2223!A32," ",CALC2223!C32," ",CALC2223!E32) | E33: =CONCATENATE(CALC2223!G32," ",CALC2223!I32," ",CALC2223!K32) | F33: =CONCATENATE(CALC2223!M32," ",CALC2223!O32," ",CALC2223!Q32) | G33: =CONCATENATE(CALC2223!S32," ",CALC2223!U32," ",CALC2223!W32) | H33: =CONCATENATE(CALC2223!Y32," ",CALC2223!AA32," ",CALC2223!AC32) -> Rep BI | I33: =CONCATENATE(CALC2223!AE32," ",CALC2223!AG32," ",CALC2223!AI32) | J33: =CONCATENATE(CALC2223!AK32," ",CALC2223!AM32," ",CALC2223!AO32) | K33: =CONCATENATE(CALC2223!AQ32," ",CALC2223!AS32," ",CALC2223!AU32," ",CALC2223!AW32) -> ouderavond G1 (19 u) en G4 (20 u) | L33: =IF(C33<TODAY(),"verleden","actueel") -> verleden | N33: =OR(VALUE(CALC2223!B32)>VALUE(LASTV),VALUE(CALC2223!D32)>VALUE(LASTV),VALUE(CALC2223!F32)>VALUE(LASTV)) -> FALSE | O33: =OR(VALUE(CALC2223!H32)>VALUE(LASTV),VALUE(CALC2223!J32)>VALUE(LASTV),VALUE(CALC2223!L32)>VALUE(LASTV)) -> FALSE | P33: =OR(VALUE(CALC2223!N32)>VALUE(LASTV),VALUE(CALC2223!P32)>VALUE(LASTV),VALUE(CALC2223!R32)>VALUE(LASTV)) -> FALSE | Q33: =OR(VALUE(CALC2223!T32)>VALUE(LASTV),VALUE(CALC2223!V32)>VALUE(LASTV),VALUE(CALC2223!X32)>VALUE(LASTV)) -> FALSE | R33: =OR(VALUE(CALC2223!Z32)>VALUE(LASTV),VALUE(CALC2223!AB32)>VALUE(LASTV),VALUE(CALC2223!AD32)>VALUE(LASTV)) -> FALSE | S33: =OR(VALUE(CALC2223!AF32)>VALUE(LASTV),VALUE(CALC2223!AH32)>VALUE(LASTV),VALUE(CALC2223!AJ32)>VALUE(LASTV)) -> FALSE | T33: =OR(VALUE(CALC2223!AL32)>VALUE(LASTV),VALUE(CALC2223!AN32)>VALUE(LASTV),VALUE(CALC2223!AP32)>VALUE(LASTV)) -> FALSE | U33: =OR(VALUE(CALC2223!AR32)>VALUE(LASTV),VALUE(CALC2223!AT32)>VALUE(LASTV),VALUE(CALC2223!AV32)>VALUE(LASTV)) -> FALSE
B34: do | C34: 45932 | D34: =CONCATENATE(CALC2223!A33," ",CALC2223!C33," ",CALC2223!E33) | E34: =CONCATENATE(CALC2223!G33," ",CALC2223!I33," ",CALC2223!K33) | F34: =CONCATENATE(CALC2223!M33," ",CALC2223!O33," ",CALC2223!Q33) -> Rep GES | G34: =CONCATENATE(CALC2223!S33," ",CALC2223!U33," ",CALC2223!W33) | H34: =CONCATENATE(CALC2223!Y33," ",CALC2223!AA33," ",CALC2223!AC33) | I34: =CONCATENATE(CALC2223!AE33," ",CALC2223!AG33," ",CALC2223!AI33) -> LO1:3 | J34: =CONCATENATE(CALC2223!AK33," ",CALC2223!AM33," ",CALC2223!AO33) -> secties#2/afscheid Jeanette | K34: =CONCATENATE(CALC2223!AQ33," ",CALC2223!AS33," ",CALC2223!AU33," ",CALC2223!AW33) | L34: =IF(C34<TODAY(),"verleden","actueel") -> verleden | N34: =OR(VALUE(CALC2223!B33)>VALUE(LASTV),VALUE(CALC2223!D33)>VALUE(LASTV),VALUE(CALC2223!F33)>VALUE(LASTV)) -> FALSE | O34: =OR(VALUE(CALC2223!H33)>VALUE(LASTV),VALUE(CALC2223!J33)>VALUE(LASTV),VALUE(CALC2223!L33)>VALUE(LASTV)) -> FALSE | P34: =OR(VALUE(CALC2223!N33)>VALUE(LASTV),VALUE(CALC2223!P33)>VALUE(LASTV),VALUE(CALC2223!R33)>VALUE(LASTV)) -> FALSE | Q34: =OR(VALUE(CALC2223!T33)>VALUE(LASTV),VALUE(CALC2223!V33)>VALUE(LASTV),VALUE(CALC2223!X33)>VALUE(LASTV)) -> FALSE | R34: =OR(VALUE(CALC2223!Z33)>VALUE(LASTV),VALUE(CALC2223!AB33)>VALUE(LASTV),VALUE(CALC2223!AD33)>VALUE(LASTV)) -> FALSE | S34: =OR(VALUE(CALC2223!AF33)>VALUE(LASTV),VALUE(CALC2223!AH33)>VALUE(LASTV),VALUE(CALC2223!AJ33)>VALUE(LASTV)) -> FALSE | T34: =OR(VALUE(CALC2223!AL33)>VALUE(LASTV),VALUE(CALC2223!AN33)>VALUE(LASTV),VALUE(CALC2223!AP33)>VALUE(LASTV)) -> FALSE | U34: =OR(VALUE(CALC2223!AR33)>VALUE(LASTV),VALUE(CALC2223!AT33)>VALUE(LASTV),VALUE(CALC2223!AV33)>VALUE(LASTV)) -> FALSE
B35: vr | C35: 45933 | D35: =CONCATENATE(CALC2223!A34," ",CALC2223!C34," ",CALC2223!E34) | E35: =CONCATENATE(CALC2223!G34," ",CALC2223!I34," ",CALC2223!K34) -> Rep BIO | F35: =CONCATENATE(CALC2223!M34," ",CALC2223!O34," ",CALC2223!Q34) | G35: =CONCATENATE(CALC2223!S34," ",CALC2223!U34," ",CALC2223!W34) | H35: =CONCATENATE(CALC2223!Y34," ",CALC2223!AA34," ",CALC2223!AC34) | I35: =CONCATENATE(CALC2223!AE34," ",CALC2223!AG34," ",CALC2223!AI34) -> PWS conceptversie | J35: =CONCATENATE(CALC2223!AK34," ",CALC2223!AM34," ",CALC2223!AO34) | K35: =CONCATENATE(CALC2223!AQ34," ",CALC2223!AS34," ",CALC2223!AU34," ",CALC2223!AW34) | L35: =IF(C35<TODAY(),"verleden","actueel") -> verleden | N35: =OR(VALUE(CALC2223!B34)>VALUE(LASTV),VALUE(CALC2223!D34)>VALUE(LASTV),VALUE(CALC2223!F34)>VALUE(LASTV)) -> FALSE | O35: =OR(VALUE(CALC2223!H34)>VALUE(LASTV),VALUE(CALC2223!J34)>VALUE(LASTV),VALUE(CALC2223!L34)>VALUE(LASTV)) -> FALSE | P35: =OR(VALUE(CALC2223!N34)>VALUE(LASTV),VALUE(CALC2223!P34)>VALUE(LASTV),VALUE(CALC2223!R34)>VALUE(LASTV)) -> FALSE | Q35: =OR(VALUE(CALC2223!T34)>VALUE(LASTV),VALUE(CALC2223!V34)>VALUE(LASTV),VALUE(CALC2223!X34)>VALUE(LASTV)) -> FALSE | R35: =OR(VALUE(CALC2223!Z34)>VALUE(LASTV),VALUE(CALC2223!AB34)>VALUE(LASTV),VALUE(CALC2223!AD34)>VALUE(LASTV)) -> FALSE | S35: =OR(VALUE(CALC2223!AF34)>VALUE(LASTV),VALUE(CALC2223!AH34)>VALUE(LASTV),VALUE(CALC2223!AJ34)>VALUE(LASTV)) -> FALSE | T35: =OR(VALUE(CALC2223!AL34)>VALUE(LASTV),VALUE(CALC2223!AN34)>VALUE(LASTV),VALUE(CALC2223!AP34)>VALUE(LASTV)) -> FALSE | U35: =OR(VALUE(CALC2223!AR34)>VALUE(LASTV),VALUE(CALC2223!AT34)>VALUE(LASTV),VALUE(CALC2223!AV34)>VALUE(LASTV)) -> FALSE
B36: za | C36: 45934 | D36: =CONCATENATE(CALC2223!A35," ",CALC2223!C35," ",CALC2223!E35) | E36: =CONCATENATE(CALC2223!G35," ",CALC2223!I35," ",CALC2223!K35) | F36: =CONCATENATE(CALC2223!M35," ",CALC2223!O35," ",CALC2223!Q35) | G36: =CONCATENATE(CALC2223!S35," ",CALC2223!U35," ",CALC2223!W35) | H36: =CONCATENATE(CALC2223!Y35," ",CALC2223!AA35," ",CALC2223!AC35) | I36: =CONCATENATE(CALC2223!AE35," ",CALC2223!AG35," ",CALC2223!AI35) | J36: =CONCATENATE(CALC2223!AK35," ",CALC2223!AM35," ",CALC2223!AO35) | K36: =CONCATENATE(CALC2223!AQ35," ",CALC2223!AS35," ",CALC2223!AU35," ",CALC2223!AW35) | L36: =IF(C36<TODAY(),"verleden","actueel") -> verleden | N36: =OR(VALUE(CALC2223!B35)>VALUE(LASTV),VALUE(CALC2223!D35)>VALUE(LASTV),VALUE(CALC2223!F35)>VALUE(LASTV)) -> FALSE | O36: =OR(VALUE(CALC2223!H35)>VALUE(LASTV),VALUE(CALC2223!J35)>VALUE(LASTV),VALUE(CALC2223!L35)>VALUE(LASTV)) -> FALSE | P36: =OR(VALUE(CALC2223!N35)>VALUE(LASTV),VALUE(CALC2223!P35)>VALUE(LASTV),VALUE(CALC2223!R35)>VALUE(LASTV)) -> FALSE | Q36: =OR(VALUE(CALC2223!T35)>VALUE(LASTV),VALUE(CALC2223!V35)>VALUE(LASTV),VALUE(CALC2223!X35)>VALUE(LASTV)) -> FALSE | R36: =OR(VALUE(CALC2223!Z35)>VALUE(LASTV),VALUE(CALC2223!AB35)>VALUE(LASTV),VALUE(CALC2223!AD35)>VALUE(LASTV)) -> FALSE | S36: =OR(VALUE(CALC2223!AF35)>VALUE(LASTV),VALUE(CALC2223!AH35)>VALUE(LASTV),VALUE(CALC2223!AJ35)>VALUE(LASTV)) -> FALSE | T36: =OR(VALUE(CALC2223!AL35)>VALUE(LASTV),VALUE(CALC2223!AN35)>VALUE(LASTV),VALUE(CALC2223!AP35)>VALUE(LASTV)) -> FALSE | U36: =OR(VALUE(CALC2223!AR35)>VALUE(LASTV),VALUE(CALC2223!AT35)>VALUE(LASTV),VALUE(CALC2223!AV35)>VALUE(LASTV)) -> FALSE
B37: zo | C37: 45935 | D37: =CONCATENATE(CALC2223!A36," ",CALC2223!C36," ",CALC2223!E36) | E37: =CONCATENATE(CALC2223!G36," ",CALC2223!I36," ",CALC2223!K36) | F37: =CONCATENATE(CALC2223!M36," ",CALC2223!O36," ",CALC2223!Q36) | G37: =CONCATENATE(CALC2223!S36," ",CALC2223!U36," ",CALC2223!W36) | H37: =CONCATENATE(CALC2223!Y36," ",CALC2223!AA36," ",CALC2223!AC36) | I37: =CONCATENATE(CALC2223!AE36," ",CALC2223!AG36," ",CALC2223!AI36) | J37: =CONCATENATE(CALC2223!AK36," ",CALC2223!AM36," ",CALC2223!AO36) | K37: =CONCATENATE(CALC2223!AQ36," ",CALC2223!AS36," ",CALC2223!AU36," ",CALC2223!AW36) | L37: =IF(C37<TODAY(),"verleden","actueel") -> verleden | N37: =OR(VALUE(CALC2223!B36)>VALUE(LASTV),VALUE(CALC2223!D36)>VALUE(LASTV),VALUE(CALC2223!F36)>VALUE(LASTV)) -> FALSE | O37: =OR(VALUE(CALC2223!H36)>VALUE(LASTV),VALUE(CALC2223!J36)>VALUE(LASTV),VALUE(CALC2223!L36)>VALUE(LASTV)) -> FALSE | P37: =OR(VALUE(CALC2223!N36)>VALUE(LASTV),VALUE(CALC2223!P36)>VALUE(LASTV),VALUE(CALC2223!R36)>VALUE(LASTV)) -> FALSE | Q37: =OR(VALUE(CALC2223!T36)>VALUE(LASTV),VALUE(CALC2223!V36)>VALUE(LASTV),VALUE(CALC2223!X36)>VALUE(LASTV)) -> FALSE | R37: =OR(VALUE(CALC2223!Z36)>VALUE(LASTV),VALUE(CALC2223!AB36)>VALUE(LASTV),VALUE(CALC2223!AD36)>VALUE(LASTV)) -> FALSE | S37: =OR(VALUE(CALC2223!AF36)>VALUE(LASTV),VALUE(CALC2223!AH36)>VALUE(LASTV),VALUE(CALC2223!AJ36)>VALUE(LASTV)) -> FALSE | T37: =OR(VALUE(CALC2223!AL36)>VALUE(LASTV),VALUE(CALC2223!AN36)>VALUE(LASTV),VALUE(CALC2223!AP36)>VALUE(LASTV)) -> FALSE | U37: =OR(VALUE(CALC2223!AR36)>VALUE(LASTV),VALUE(CALC2223!AT36)>VALUE(LASTV),VALUE(CALC2223!AV36)>VALUE(LASTV)) -> FALSE
A38: 41 | B38: ma | C38: 45936 | D38: =CONCATENATE(CALC2223!A37," ",CALC2223!C37," ",CALC2223!E37) | E38: =CONCATENATE(CALC2223!G37," ",CALC2223!I37," ",CALC2223!K37) | F38: =CONCATENATE(CALC2223!M37," ",CALC2223!O37," ",CALC2223!Q37) | G38: =CONCATENATE(CALC2223!S37," ",CALC2223!U37," ",CALC2223!W37) | H38: =CONCATENATE(CALC2223!Y37," ",CALC2223!AA37," ",CALC2223!AC37) -> SE AK | I38: =CONCATENATE(CALC2223!AE37," ",CALC2223!AG37," ",CALC2223!AI37) | J38: =CONCATENATE(CALC2223!AK37," ",CALC2223!AM37," ",CALC2223!AO37) | K38: =CONCATENATE(CALC2223!AQ37," ",CALC2223!AS37," ",CALC2223!AU37," ",CALC2223!AW37) | L38: =IF(C38<TODAY(),"verleden","actueel") -> verleden | N38: =OR(VALUE(CALC2223!B37)>VALUE(LASTV),VALUE(CALC2223!D37)>VALUE(LASTV),VALUE(CALC2223!F37)>VALUE(LASTV)) -> FALSE | O38: =OR(VALUE(CALC2223!H37)>VALUE(LASTV),VALUE(CALC2223!J37)>VALUE(LASTV),VALUE(CALC2223!L37)>VALUE(LASTV)) -> FALSE | P38: =OR(VALUE(CALC2223!N37)>VALUE(LASTV),VALUE(CALC2223!P37)>VALUE(LASTV),VALUE(CALC2223!R37)>VALUE(LASTV)) -> FALSE | Q38: =OR(VALUE(CALC2223!T37)>VALUE(LASTV),VALUE(CALC2223!V37)>VALUE(LASTV),VALUE(CALC2223!X37)>VALUE(LASTV)) -> FALSE | R38: =OR(VALUE(CALC2223!Z37)>VALUE(LASTV),VALUE(CALC2223!AB37)>VALUE(LASTV),VALUE(CALC2223!AD37)>VALUE(LASTV)) -> FALSE | S38: =OR(VALUE(CALC2223!AF37)>VALUE(LASTV),VALUE(CALC2223!AH37)>VALUE(LASTV),VALUE(CALC2223!AJ37)>VALUE(LASTV)) -> FALSE | T38: =OR(VALUE(CALC2223!AL37)>VALUE(LASTV),VALUE(CALC2223!AN37)>VALUE(LASTV),VALUE(CALC2223!AP37)>VALUE(LASTV)) -> FALSE | U38: =OR(VALUE(CALC2223!AR37)>VALUE(LASTV),VALUE(CALC2223!AT37)>VALUE(LASTV),VALUE(CALC2223!AV37)>VALUE(LASTV)) -> FALSE
